Workbook
Name p_sc: Supuestos!$B$3
Name p_sl: Supuestos!$B$4
Name p_reg_m: Supuestos!$G$7
Name p_lead_days: Supuestos!$G$8
Name p_ship_m: Supuestos!$G$9
Name p_ramp_m: Supuestos!$G$10
Name p_cen_start: Supuestos!$G$11
Name p_mkt: Supuestos!$G$12
Name p_share_dec: Supuestos!$G$13
Name p_pwin_cen: Supuestos!$G$14
Name p_realiz: Supuestos!$G$15
Name p_realiz_minsa: Supuestos!$G$16
Name p_minsa_occ: Supuestos!$G$17
Name p_cc_w: Supuestos!$G$18
Name p_pf_dec: Supuestos!$G$19
Name p_pf_cen: Supuestos!$G$20
Name p_erosion: Supuestos!$G$21
Name p_gm_dec: Supuestos!$G$22
Name p_gm_cen: Supuestos!$G$23
Name p_sup_idx: Supuestos!$G$24
Name p_pack: Supuestos!$G$25
Name p_log_mult: Supuestos!$G$26
Name p_dist: Supuestos!$G$27
Name p_penal: Supuestos!$G$28
Name p_expiry: Supuestos!$G$29
Name p_baddebt: Supuestos!$G$30
Name p_dso_days: Supuestos!$G$31
Name p_cover_m: Supuestos!$G$32
Name p_cen_stock_m: Supuestos!$G$33
Name p_adv: Supuestos!$G$34
Name p_credit_days: Supuestos!$G$35
Name p_bond_css: Supuestos!$G$36
Name p_bond_minsa: Supuestos!$G$37
Name p_collat: Supuestos!$G$38
Name p_bond_prem: Supuestos!$G$39
Name p_bid_bond: Supuestos!$G$40
Name p_bid_m: Supuestos!$G$41
Name p_mincash_m: Supuestos!$G$42
Name p_rs_off: Supuestos!$G$43
Name p_rs_iea: Supuestos!$G$44
Name p_rs_law: Supuestos!$G$45
Name p_rs_smp: Supuestos!$G$46
Name p_rs_trad: Supuestos!$G$47
Name p_rs_succ: Supuestos!$G$48
Name p_postreg: Supuestos!$G$49
Name p_n2: Supuestos!$G$50
Name p_m2: Supuestos!$G$51
Name p_rel2: Supuestos!$G$52
Name p_fact_share: Supuestos!$G$53
Name p_fact_cost: Supuestos!$G$54
Name p_stop_det: Supuestos!$G$55
Name p_inv_liq: Supuestos!$G$56
Name p_isr: Supuestos!$G$57
Name p_divtax: Supuestos!$G$58
Name p_aviso: Supuestos!$G$59
Name p_oncost: Supuestos!$G$60
Name p_itbms_srv: Supuestos!$G$61
Name p_payout: Supuestos!$G$62
Name p_disc: Supuestos!$G$63
Name p_recov: Supuestos!$G$64

Sheet Léeme
A1: Modelo financiero: distribuidora de medicamentos para compras públicas en Panamá
A2: Versión auditada del 9 de octubre de 2026. Cifras en balboas (B/. = US$). Mes 1 del modelo = enero de 2027.
A4: Cómo usarlo
A5: 1. Elija el escenario en Supuestos!B3 (1 = pesimista, 2 = base, 3 = optimista). Todo el modelo se recalcula.
A6: 2. Cambie cualquier valor azul de las columnas D, E o F de Supuestos, o la columna «Incluir» de SKUs, para probar otra hipótesis.
A7: 3. Supuestos!B4 = 1 aplica las tarifas de la propuesta de SignatureLex en lugar de las de mercado.
A8: 4. Resultados vivos: Valoración (VPN, TIR, múltiplo, capital), Anual (estado de resultados e impuestos), Mensual (flujo de caja).
A9: 5. Las hojas Escenarios, Simulación y Sensibilidad son resultados fijos del motor en Python; no cambian al editar supuestos.
A11: Convenciones
A12: Texto azul = dato de entrada editable. Negro = fórmula. Verde = vínculo a otra hoja. Relleno amarillo = supuestos clave.
A13: En la columna Fuente: F = dato verificado en fuente abierta; R = referencia indirecta; E = estimación propia pendiente de cotización.
A15: Lógica del modelo (mes a mes, 60 meses desde la constitución de la S.A.)
... A31: El capital del caso base es un valor esperado sin fallas; para dimensionar el capital use los percentiles de la hoja Simulación.

Sheet Supuestos
A1: Supuestos
A3: Escenario | B3: 2 | C3: =CHOOSE($B$3,"Pesimista","Base","Optimista")
A4: SignatureLex | B4: 0 | C4: Usar tarifas de la propuesta de SignatureLex (1) o de mercado (0)
A6: Clave | B6: Parámetro | C6: Unidad | D6: Pesimista | E6: Base | F6: Optimista | G6: Usado | H6: Fuente o base
A7: reg_m | B7: Mes en que salen los registros sanitarios (presentados en el mes 3) | C7: mes | D7: 12 | E7: 9 | F7: 7 | G7: =CHOOSE(p_sc,D7,E7,F7) | H7: F: Ley 419 arts. 41 y 74 (20 días hábiles de la DNFD y 60 del laboratorio, unos 4 meses); E: base con 2 meses de observaciones, pesimista con subsanación y rezago
A8: lead_days | B8: Tiempo de reposición: orden al proveedor hasta stock en Panamá | C8: días | D8: 120 | E8: 90 | F8: 75 | G8: =CHOOSE(p_sc,D8,E8,F8) | H8: E: producción, flete marítimo con transbordo y aduana; se confirma con la fábrica y el agente de carga
A9: ship_m | B9: Meses entre embarque y stock disponible | C9: meses | D9: 2 | E9: 2 | F9: 2 | G9: =CHOOSE(p_sc,D9,E9,F9) | H9: E: tránsito con transbordo y desaduanaje
A10: ramp_m | B10: Meses para llegar a la participación madura en compras descentralizadas | C10: meses | D10: 18 | E10: 12 | F10: 9 | G10: =CHOOSE(p_sc,D10,E10,F10) | H10: E: curva de aprendizaje; los nuevos son descalificados 57% de las veces frente a 36% de los establecidos (OCDS MINSA 2021-2024)
A11: cen_start | B11: Mes en que podría arrancar el primer contrato centralizado (calendario de la LPU) | C11: mes | D11: 27 | E11: 20 | F11: 13 | G11: =CHOOSE(p_sc,D11,E11,F11) | H11: F: la LPU 01-2026 vence el 11-may-2027 y la siguiente se licitaría entre dic-2026 y feb-2027, antes de tener registros; la que sigue arrancaría hacia ago-2028 (mes 20). Optimista: la CSS prorroga y licita a inicios de 2028; pesimista: el calendario se corre 7 meses
A12: mkt | B12: Factor de mercado (demanda futura frente a 2025-2026) | C12: x | D12: 0.75 | E12: 0.9 | F12: 1 | G12: =CHOOSE(p_sc,D12,E12,F12) | H12: F: presupuesto de medicamentos de la CSS 2027 de B/.230.3 millones (-28.6%), en trámite; la CSS gastó en 2026 el 64% de lo presupuestado
A13: share_dec | B13: Participación madura en compras descentralizadas (valor) | C13: % | D13: 0.1 | E13: 0.22 | F13: 0.32 | G13: =CHOOSE(p_sc,D13,E13,F13) | H13: E: los nuevos ganan 36.6% de sus ofertas con precio (OCDS MINSA 2021-2024), ofertando en parte de los actos
A14: pwin_cen | B14: Probabilidad de ganar un renglón centralizado en el que se oferta | C14: % | D14: 0.15 | E14: 0.3 | F14: 0.45 | G14: =CHOOSE(p_sc,D14,E14,F14) | H14: F: los nuevos ganan 36.6% por oferta en el MINSA y la LPU 01-2026 da 39.9% por oferta; E: descuento por descalificación
A15: realiz | B15: Cantidad comprada frente a la máxima del contrato de la LPU | C15: % | D15: 0.55 | E15: 0.75 | F15: 0.9 | G15: =CHOOSE(p_sc,D15,E15,F15) | H15: F: compra mínima garantizada de 50% (Adenda 1 de la LPU 01-2026); E: el resto
A16: realiz_minsa | B16: Cantidad comprada frente a la del contrato del MINSA (subasta por cantidad fija) | C16: % | D16: 1 | E16: 1 | F16: 1 | G16: =CHOOSE(p_sc,D16,E16,F16) | H16: F: las subastas del MINSA de 2026 son por cantidad fija (informe de la SSR-000018)
A17: minsa_occ | B17: Probabilidad de que el MINSA haga su compra centralizada en el año | C17: % | D17: 0.3 | E17: 0.5 | F17: 0.7 | G17: =CHOOSE(p_sc,D17,E17,F17) | H17: F: 33 subastas del MINSA entre el 24-mar y el 29-may-2026 y ninguna después; la compra conjunta del DE 16 no tiene acto a octubre de 2026
A18: cc_w | B18: Parte de la cantidad de la compra conjunta de 2023 que se toma como demanda del MINSA | C18: % | D18: 0 | E18: 0.15 | F18: 0.5 | G18: =CHOOSE(p_sc,D18,E18,F18) | H18: F: de los renglones de la primera ola solo 3 de 9 aparecen como contratos y por 7-20% de lo pedido; las cifras de 2023 son ofertas, no adjudicaciones
... A43: rs_off | B43: Tasas oficiales por registro (DNFD 500 + MEF + refrendo) | C43: B/. | D43: 575 | E43: 570 | F43: 545 | G43: =CHOOSE(p_sc,D43,E43,F43) | H43: F: DE 27 art. 15; guía del MINSA de 2012 para MEF y refrendo
A44: rs_iea | B44: Análisis de control previo (IEA o INDICASAT) por producto | C44: B/. | D44: 2000 | E44: 1500 | F44: 1000 | G44: =IF(p_sl=1,1500,CHOOSE(p_sc,D44,E44,F44)) | H44: R: guía del MINSA de 2012 US$1,000; SignatureLex B/.1,500; la tarifa vigente no está publicada pese a la Ley 419 art. 79
A45: rs_law | B45: Honorario y gastos del abogado por registro | C45: B/. | D45: 1350 | E45: 800 | F45: 500 | G45: =IF(p_sl=1,1350,CHOOSE(p_sc,D45,E45,F45)) | H45: R: SignatureLex 600 + 750; arancel de 2001 B/.350
A46: rs_smp | B46: Muestras y courier por registro | C46: B/. | D46: 300 | E46: 150 | F46: 100 | G46: =CHOOSE(p_sc,D46,E46,F46) | H46: E
A47: rs_trad | B47: Traducciones oficiales por registro (CPP, BPM, poderes, etiquetas) | C47: B/. | D47: 1500 | E47: 600 | F47: 300 | G47: =CHOOSE(p_sc,D47,E47,F47) | H47: F: DE 27 art. 220 exige traductor público autorizado; E: monto
A48: rs_succ | B48: Registros aprobados / presentados | C48: % | D48: 0.7 | E48: 0.85 | F48: 0.95 | G48: =CHOOSE(p_sc,D48,E48,F48) | H48: E
A49: postreg | B49: Análisis posregistro por producto (2 en 5 años), por año | C49: B/. | D49: 800 | E49: 600 | F49: 400 | G49: =CHOOSE(p_sc,D49,E49,F49) | H49: F: Ley 419 art. 67; R: 2 x 1,500 / 5
A50: n2 | B50: Productos de la segunda ola (sin equivalencia terapéutica, fabricación verificada) | C50: productos | D50: 0 | E50: 6 | F50: 12 | G50: =CHOOSE(p_sc,D50,E50,F50) | H50: E: candidatos del catálogo con compras públicas; exigen prueba de licencia de fabricación de cada uno
A51: m2 | B51: Mes en que se presentan los registros de la segunda ola | C51: mes | D51: 24 | E51: 18 | F51: 15 | G51: =CHOOSE(p_sc,D51,E51,F51) | H51: Decisión: solo si la primera ola pasa la compuerta operativa
A52: rel2 | B52: Ingreso por producto de la segunda ola frente al promedio de la primera | C52: x | D52: 0.5 | E52: 0.7 | F52: 1 | G52: =CHOOSE(p_sc,D52,E52,F52) | H52: E
A53: fact_share | B53: Porcentaje de las ventas que se factoriza | C53: % | D53: 0 | E53: 0 | F53: 0 | G53: =CHOOSE(p_sc,D53,E53,F53) | H53: Opción; Ley 22 art. 97 permite ceder créditos
A54: fact_cost | B54: Costo mensual del factoring sobre lo cedido | C54: % | D54: 0.015 | E54: 0.0125 | F54: 0.01 | G54: =CHOOSE(p_sc,D54,E54,F54) | H54: R: Balboa Factoring 2025, 14.6-18.3% anual
A55: stop_det | B55: Mes de cierre del negocio (61 = no se cierra) | C55: mes | D55: 61 | E55: 61 | F55: 61 | G55: =CHOOSE(p_sc,D55,E55,F55) | H55: Interruptor
A56: inv_liq | B56: Recuperación del inventario si se cierra | C56: % | D56: 0.5 | E56: 0.5 | F56: 0.5 | G56: =CHOOSE(p_sc,D56,E56,F56) | H56: E
A57: isr | B57: Impuesto sobre la renta | C57: % | D57: 0.25 | E57: 0.25 | F57: 0.25 | G57: =CHOOSE(p_sc,D57,E57,F57) | H57: F: Código Fiscal art. 699
... A72: forfeit_frac | B72: Parte de la fianza de cumplimiento que se pierde si el Estado la ejecuta | C72: % | D72: 1 | E72: 1 | F72: 1 | G72: =CHOOSE(p_sc,D72,E72,F72) | H72: F: Ley 22 (ejecución de la fianza) y contragarantías de la aseguradora (pagaré, codeudores)
A74: Costos fijos mensuales (B/./mes)
A75: # | B75: Concepto | C75: Inicio | D75: Pesimista | E75: Base | F75: Optimista | G75: Usado (con cargas o ITBMS) | H75: Fuente o base | I75: Mes inicio | J75: Tipo
A76: 1 | B76: Regente farmacéutico (medio tiempo, mínimo 4 h diarias) | C76: licencia | D76: 1200 | E76: 700 | F76: 450 | G76: =CHOOSE(p_sc,D76,E76,F76)*(1+p_oncost) | H76: F: DE 27 art. 382; R: SignatureLex 400-500 al mes; Paylab 1,339-3,228 a tiempo completo | I76: =c_lic_m | J76: sueldo + cargas laborales
A77: 2 | B77: Operador logístico (3PL) licenciado: cuota mínima | C77: licencia | D77: 1200 | E77: 600 | F77: 300 | G77: =CHOOSE(p_sc,D77,E77,F77)*(1+p_itbms_srv) | H77: E: sin tarifa pública; cotizaciones pedidas | I77: =c_lic_m | J77: servicio + ITBMS
A78: 3 | B78: Contabilidad e impuestos | C78: mes 1 | D78: 450 | E78: 300 | F78: 200 | G78: =CHOOSE(p_sc,D78,E78,F78)*(1+p_itbms_srv) | H78: R: Healy Consultants 2026, unos 192 al mes; E | I78: =1 | J78: servicio + ITBMS
A79: 4 | B79: Auditoría anual de estados financieros, prorrateada | C79: mes 1 | D79: 400 | E79: 250 | F79: 150 | G79: =CHOOSE(p_sc,D79,E79,F79)*(1+p_itbms_srv) | H79: F: el Registro Nacional de Oferentes pide solvencia certificada por CPA o banco (DE 27 arts. 724-725); E: costo | I79: =1 | J79: servicio + ITBMS
A80: 5 | B80: Asesoría legal por hora (sin iguala) | C80: mes 1 | D80: 800 | E80: 300 | F80: 150 | G80: =CHOOSE(p_sc,D80,E80,F80)*(1+p_itbms_srv) | H80: R: SignatureLex B/.300 por hora; E: horas | I80: =1 | J80: servicio + ITBMS
A81: 6 | B81: Coordinador de licitaciones y operaciones (medio tiempo, desde la licencia) | C81: licencia | D81: 1000 | E81: 700 | F81: 550 | G81: =CHOOSE(p_sc,D81,E81,F81)*(1+p_oncost) | H81: R: Konzerta mayo de 2026, semi-senior a jefatura US$1,033-1,291 a tiempo completo; a medio tiempo | I81: =c_lic_m | J81: sueldo + cargas laborales
...

Sheet SKUs
A1: Portafolio y economía por producto
A2: Demanda pública anualizada (LPU 01-2026; subasta del MINSA de 2026 o compra conjunta de 2023 x p_cc_w; compras menores 2025-2026 con precio ponderado). Ventas a madurez antes de rampa y erosión.
A3: Canales: LPU = licitación de precio único de la CSS; MINSA central = subasta en reversa o compra conjunta; desc. = contratación menor y compra menor ágil. Costo = referencia FOB x índice x (1 + empaque) + logística.
A5: ID | B5: Producto | C5: Grupo | D5: Incluir (1/0) | E5: FOB base (B/./u) | F5: Logística (B/./u) | G5: Fuente del costo | H5: CSS LPU: unid./año | I5: CSS LPU: precio | J5: MINSA central: unid./año | K5: MINSA central: precio | L5: CSS desc.: unid./año | M5: CSS desc.: precio | N5: MINSA/patronatos desc.: unid./año | O5: MINSA/patronatos desc.: precio | P5: Costo puesto en Panamá | Q5: Precio oferta LPU | R5: Precio oferta MINSA central | S5: Precio oferta CSS desc. | T5: Precio oferta MINSA desc. | U5: Margen LPU | V5: Margen MINSA central | W5: Margen CSS desc. | X5: Margen MINSA desc. | Y5: Oferta LPU | Z5: Oferta MINSA central | AA5: Oferta CSS desc. | AB5: Oferta MINSA desc. | AC5: Ventas CSS desc. (madurez) | AD5: Ventas MINSA desc. (madurez) | AE5: Ventas LPU si gana | AF5: Ventas MINSA central si gana | AG5: Costo CSS desc. | AH5: Costo MINSA desc. | AI5: Costo LPU | AJ5: Costo MINSA central | AK5: Ventas esperadas año maduro | AL5: Utilidad bruta esperada | AM5: Costo FOB (para Zywie) | AN5: Oferta LPU con fianza de propuesta (B/./año)
A6: PCT500 | B6: Paracetamol 500 mg tableta | C6: Primera ola | D6: 1 | E6: 0.0038 | F6: 0.00165 | G6: R: PMBI 2024-27 INR 2.74 por 10, TNMSC 2024 INR 23.48 por 100 y Assam 2025 INR 2.50 por 10; x1.4 = US$0.0034-0.0040; se usa 0.0038; blíster 5.5 cm3 | H6: 23770516 | I6: 0.01 | J6: 0 | K6: 0 | L6: 1141333 | M6: 0.02 | N6: 11112486 | O6: 0.0201 | P6: =E6*p_sup_idx*(1+p_pack)+F6*p_log_mult | Q6: =I6*p_pf_cen | R6: =K6*p_pf_cen | S6: =M6*p_pf_dec | T6: =O6*p_pf_dec | U6: =IF(Q6>0,1-P6/Q6,-9) | V6: =IF(R6>0,1-P6/R6,-9) | W6: =IF(S6>0,1-P6/S6,-9) | X6: =IF(T6>0,1-P6/T6,-9) | Y6: =IF(AND($D6=1,H6>0,U6>=p_gm_cen),1,0) | Z6: =IF(AND($D6=1,J6>0,V6>=p_gm_cen),1,0) | AA6: =IF(AND($D6=1,L6>0,W6>=p_gm_dec),1,0) | AB6: =IF(AND($D6=1,N6>0,X6>=p_gm_dec),1,0) | AC6: =AA6*L6*p_mkt*S6*p_rs_succ*p_share_dec | AD6: =AB6*N6*p_mkt*T6*p_rs_succ*p_share_dec | AE6: =Y6*H6*p_mkt*Q6*p_rs_succ*p_realiz | AF6: =Z6*J6*p_mkt*R6*p_rs_succ*p_realiz_minsa | AG6: =IF(S6>0,AC6*P6/S6,0) | AH6: =IF(T6>0,AD6*P6/T6,0) | AI6: =IF(Q6>0,AE6*P6/Q6,0) | AJ6: =IF(R6>0,AF6*P6/R6,0) | AK6: =AC6+AD6+AE6*p_pwin_cen+AF6*p_pwin_cen*p_minsa_occ | AL6: =(AC6-AG6)+(AD6-AH6)+(AE6-AI6)*p_pwin_cen+(AF6-AJ6)*p_pwin_cen*p_minsa_occ | AM6: =IF(P6>0,E6*p_sup_idx*(1+p_pack)/P6,0) | AN6: =IF(AND(Y6=1,H6>0),H6*p_mkt*Q6*p_rs_succ,0)
A7: PCTSYR | B7: Paracetamol 120-160 mg/5 ml jarabe, frasco 120 ml | C7: Primera ola | D7: 1 | E7: 0.1478 | F7: 0.135 | G7: R: TNMSC 2024 INR 5.72 y Assam 2025 INR 5.85 por 60 ml; a 120 ml se usa INR 10.2 (factor 1.75 por frasco más grande), x1.4; 450 cm3 | H7: 315718 | I7: 0.59 | J7: 524358 | K7: 0.4 | L7: 0 | M7: 0 | N7: 63302 | O7: 0.6938 | P7: =E7*p_sup_idx*(1+p_pack)+F7*p_log_mult | Q7: =I7*p_pf_cen | R7: =K7*p_pf_cen | S7: =M7*p_pf_dec | T7: =O7*p_pf_dec | U7: =IF(Q7>0,1-P7/Q7,-9) | V7: =IF(R7>0,1-P7/R7,-9) | W7: =IF(S7>0,1-P7/S7,-9) | X7: =IF(T7>0,1-P7/T7,-9) | Y7: =IF(AND($D7=1,H7>0,U7>=p_gm_cen),1,0) | Z7: =IF(AND($D7=1,J7>0,V7>=p_gm_cen),1,0) | AA7: =IF(AND($D7=1,L7>0,W7>=p_gm_dec),1,0) | AB7: =IF(AND($D7=1,N7>0,X7>=p_gm_dec),1,0) | AC7: =AA7*L7*p_mkt*S7*p_rs_succ*p_share_dec | AD7: =AB7*N7*p_mkt*T7*p_rs_succ*p_share_dec | AE7: =Y7*H7*p_mkt*Q7*p_rs_succ*p_realiz | AF7: =Z7*J7*p_mkt*R7*p_rs_succ*p_realiz_minsa | AG7: =IF(S7>0,AC7*P7/S7,0) | AH7: =IF(T7>0,AD7*P7/T7,0) | AI7: =IF(Q7>0,AE7*P7/Q7,0) | AJ7: =IF(R7>0,AF7*P7/R7,0) | AK7: =AC7+AD7+AE7*p_pwin_cen+AF7*p_pwin_cen*p_minsa_occ | AL7: =(AC7-AG7)+(AD7-AH7)+(AE7-AI7)*p_pwin_cen+(AF7-AJ7)*p_pwin_cen*p_minsa_occ | AM7: =IF(P7>0,E7*p_sup_idx*(1+p_pack)/P7,0) | AN7: =IF(AND(Y7=1,H7>0),H7*p_mkt*Q7*p_rs_succ,0)
A8: AMCTAB | B8: Amoxicilina + clavulánico 500/125 mg tableta | C8: Primera ola | D8: 1 | E8: 0.0754 | F8: 0.0036 | G8: R: PMBI 2024-26 INR 31.60 por 6 y TNMSC 2024 INR 30.81 por 6 (se usa INR 5.2 por tableta), x1.4; alu-alu 12 cm3 | H8: 46534 | I8: 0.179 | J8: =191135*p_cc_w | K8: 0.19 | L8: 0 | M8: 0 | N8: 30555 | O8: 0.3211 | P8: =E8*p_sup_idx*(1+p_pack)+F8*p_log_mult | Q8: =I8*p_pf_cen | R8: =K8*p_pf_cen | S8: =M8*p_pf_dec | T8: =O8*p_pf_dec | U8: =IF(Q8>0,1-P8/Q8,-9) | V8: =IF(R8>0,1-P8/R8,-9) | W8: =IF(S8>0,1-P8/S8,-9) | X8: =IF(T8>0,1-P8/T8,-9) | Y8: =IF(AND($D8=1,H8>0,U8>=p_gm_cen),1,0) | Z8: =IF(AND($D8=1,J8>0,V8>=p_gm_cen),1,0) | AA8: =IF(AND($D8=1,L8>0,W8>=p_gm_dec),1,0) | AB8: =IF(AND($D8=1,N8>0,X8>=p_gm_dec),1,0) | AC8: =AA8*L8*p_mkt*S8*p_rs_succ*p_share_dec | AD8: =AB8*N8*p_mkt*T8*p_rs_succ*p_share_dec | AE8: =Y8*H8*p_mkt*Q8*p_rs_succ*p_realiz | AF8: =Z8*J8*p_mkt*R8*p_rs_succ*p_realiz_minsa | AG8: =IF(S8>0,AC8*P8/S8,0) | AH8: =IF(T8>0,AD8*P8/T8,0) | AI8: =IF(Q8>0,AE8*P8/Q8,0) | AJ8: =IF(R8>0,AF8*P8/R8,0) | AK8: =AC8+AD8+AE8*p_pwin_cen+AF8*p_pwin_cen*p_minsa_occ | AL8: =(AC8-AG8)+(AD8-AH8)+(AE8-AI8)*p_pwin_cen+(AF8-AJ8)*p_pwin_cen*p_minsa_occ | AM8: =IF(P8>0,E8*p_sup_idx*(1+p_pack)/P8,0) | AN8: =IF(AND(Y8=1,H8>0),H8*p_mkt*Q8*p_rs_succ,0)
A9: AMCSUS | B9: Amoxicilina + clavulánico 400/57 mg/5 ml suspensión, frasco 100 ml | C9: Primera ola | D9: 1 | E9: 1.159 | F9: 0.15 | G9: R: PMBI 2023-26 INR 28.06 por 30 ml, escalado a 100 ml (x2.85 = INR 80), x1.4; 500 cm3 | H9: 10217 | I9: 1.98 | J9: 0 | K9: 0 | L9: 0 | M9: 0 | N9: 7463 | O9: 4.5197 | P9: =E9*p_sup_idx*(1+p_pack)+F9*p_log_mult | Q9: =I9*p_pf_cen | R9: =K9*p_pf_cen | S9: =M9*p_pf_dec | T9: =O9*p_pf_dec | U9: =IF(Q9>0,1-P9/Q9,-9) | V9: =IF(R9>0,1-P9/R9,-9) | W9: =IF(S9>0,1-P9/S9,-9) | X9: =IF(T9>0,1-P9/T9,-9) | Y9: =IF(AND($D9=1,H9>0,U9>=p_gm_cen),1,0) | Z9: =IF(AND($D9=1,J9>0,V9>=p_gm_cen),1,0) | AA9: =IF(AND($D9=1,L9>0,W9>=p_gm_dec),1,0) | AB9: =IF(AND($D9=1,N9>0,X9>=p_gm_dec),1,0) | AC9: =AA9*L9*p_mkt*S9*p_rs_succ*p_share_dec | AD9: =AB9*N9*p_mkt*T9*p_rs_succ*p_share_dec | AE9: =Y9*H9*p_mkt*Q9*p_rs_succ*p_realiz | AF9: =Z9*J9*p_mkt*R9*p_rs_succ*p_realiz_minsa | AG9: =IF(S9>0,AC9*P9/S9,0) | AH9: =IF(T9>0,AD9*P9/T9,0) | AI9: =IF(Q9>0,AE9*P9/Q9,0) | AJ9: =IF(R9>0,AF9*P9/R9,0) | AK9: =AC9+AD9+AE9*p_pwin_cen+AF9*p_pwin_cen*p_minsa_occ | AL9: =(AC9-AG9)+(AD9-AH9)+(AE9-AI9)*p_pwin_cen+(AF9-AJ9)*p_pwin_cen*p_minsa_occ | AM9: =IF(P9>0,E9*p_sup_idx*(1+p_pack)/P9,0) | AN9: =IF(AND(Y9=1,H9>0),H9*p_mkt*Q9*p_rs_succ,0)
A10: CRO1G | B10: Ceftriaxona 1 g vial (I.V.) | C10: Primera ola | D10: 1 | E10: 0.1956 | F10: 0.0162 | G10: R: Assam 2025 INR 12.6 y Delhi 2022 INR 15.48 por vial; se usa INR 13.5, x1.4; 54 cm3 | H10: 194242 | I10: 0.239 | J10: =201135*p_cc_w | K10: 0.25 | L10: 3899 | M10: 0.78 | N10: 43743 | O10: 0.452 | P10: =E10*p_sup_idx*(1+p_pack)+F10*p_log_mult | Q10: =I10*p_pf_cen | R10: =K10*p_pf_cen | S10: =M10*p_pf_dec | T10: =O10*p_pf_dec | U10: =IF(Q10>0,1-P10/Q10,-9) | V10: =IF(R10>0,1-P10/R10,-9) | W10: =IF(S10>0,1-P10/S10,-9) | X10: =IF(T10>0,1-P10/T10,-9) | Y10: =IF(AND($D10=1,H10>0,U10>=p_gm_cen),1,0) | Z10: =IF(AND($D10=1,J10>0,V10>=p_gm_cen),1,0) | AA10: =IF(AND($D10=1,L10>0,W10>=p_gm_dec),1,0) | AB10: =IF(AND($D10=1,N10>0,X10>=p_gm_dec),1,0) | AC10: =AA10*L10*p_mkt*S10*p_rs_succ*p_share_dec | AD10: =AB10*N10*p_mkt*T10*p_rs_succ*p_share_dec | AE10: =Y10*H10*p_mkt*Q10*p_rs_succ*p_realiz | AF10: =Z10*J10*p_mkt*R10*p_rs_succ*p_realiz_minsa | AG10: =IF(S10>0,AC10*P10/S10,0) | AH10: =IF(T10>0,AD10*P10/T10,0) | AI10: =IF(Q10>0,AE10*P10/Q10,0) | AJ10: =IF(R10>0,AF10*P10/R10,0) | AK10: =AC10+AD10+AE10*p_pwin_cen+AF10*p_pwin_cen*p_minsa_occ | AL10: =(AC10-AG10)+(AD10-AH10)+(AE10-AI10)*p_pwin_cen+(AF10-AJ10)*p_pwin_cen*p_minsa_occ | AM10: =IF(P10>0,E10*p_sup_idx*(1+p_pack)/P10,0) | AN10: =IF(AND(Y10=1,H10>0),H10*p_mkt*Q10*p_rs_succ,0)
A11: CTX1G | B11: Cefotaxima 1 g vial | C11: Primera ola | D11: 1 | E11: 0.2029 | F11: 0.0162 | G11: R: Assam 2025 INR 13.3 por vial (PMBI 500 mg con agua INR 12.32); se usa INR 14.0, x1.4; 54 cm3 | H11: 168687 | I11: 0.259 | J11: =177344*p_cc_w | K11: 0.27 | L11: 0 | M11: 0 | N11: 79691 | O11: 0.3987 | P11: =E11*p_sup_idx*(1+p_pack)+F11*p_log_mult | Q11: =I11*p_pf_cen | R11: =K11*p_pf_cen | S11: =M11*p_pf_dec | T11: =O11*p_pf_dec | U11: =IF(Q11>0,1-P11/Q11,-9) | V11: =IF(R11>0,1-P11/R11,-9) | W11: =IF(S11>0,1-P11/S11,-9) | X11: =IF(T11>0,1-P11/T11,-9) | Y11: =IF(AND($D11=1,H11>0,U11>=p_gm_cen),1,0) | Z11: =IF(AND($D11=1,J11>0,V11>=p_gm_cen),1,0) | AA11: =IF(AND($D11=1,L11>0,W11>=p_gm_dec),1,0) | AB11: =IF(AND($D11=1,N11>0,X11>=p_gm_dec),1,0) | AC11: =AA11*L11*p_mkt*S11*p_rs_succ*p_share_dec | AD11: =AB11*N11*p_mkt*T11*p_rs_succ*p_share_dec | AE11: =Y11*H11*p_mkt*Q11*p_rs_succ*p_realiz | AF11: =Z11*J11*p_mkt*R11*p_rs_succ*p_realiz_minsa | AG11: =IF(S11>0,AC11*P11/S11,0) | AH11: =IF(T11>0,AD11*P11/T11,0) | AI11: =IF(Q11>0,AE11*P11/Q11,0) | AJ11: =IF(R11>0,AF11*P11/R11,0) | AK11: =AC11+AD11+AE11*p_pwin_cen+AF11*p_pwin_cen*p_minsa_occ | AL11: =(AC11-AG11)+(AD11-AH11)+(AE11-AI11)*p_pwin_cen+(AF11-AJ11)*p_pwin_cen*p_minsa_occ | AM11: =IF(P11>0,E11*p_sup_idx*(1+p_pack)/P11,0) | AN11: =IF(AND(Y11=1,H11>0),H11*p_mkt*Q11*p_rs_succ,0)
A12: ALBSUS | B12: Albendazol 400 mg/10 ml suspensión | C12: Primera ola | D12: 1 | E12: 0.07 | F12: 0.024 | G12: R: PMBI 2022-25 INR 4.22 y Delhi 2022 INR 4.59 por 10 ml; x1.4 = US$0.062; se usa 0.07; 80 cm3 (el ganador de la LPU entregó 20 ml) | H12: 18762 | I12: 1.81 | J12: =194990*p_cc_w | K12: 1.86 | L12: 0 | M12: 0 | N12: 10114 | O12: 1.5163 | P12: =E12*p_sup_idx*(1+p_pack)+F12*p_log_mult | Q12: =I12*p_pf_cen | R12: =K12*p_pf_cen | S12: =M12*p_pf_dec | T12: =O12*p_pf_dec | U12: =IF(Q12>0,1-P12/Q12,-9) | V12: =IF(R12>0,1-P12/R12,-9) | W12: =IF(S12>0,1-P12/S12,-9) | X12: =IF(T12>0,1-P12/T12,-9) | Y12: =IF(AND($D12=1,H12>0,U12>=p_gm_cen),1,0) | Z12: =IF(AND($D12=1,J12>0,V12>=p_gm_cen),1,0) | AA12: =IF(AND($D12=1,L12>0,W12>=p_gm_dec),1,0) | AB12: =IF(AND($D12=1,N12>0,X12>=p_gm_dec),1,0) | AC12: =AA12*L12*p_mkt*S12*p_rs_succ*p_share_dec | AD12: =AB12*N12*p_mkt*T12*p_rs_succ*p_share_dec | AE12: =Y12*H12*p_mkt*Q12*p_rs_succ*p_realiz | AF12: =Z12*J12*p_mkt*R12*p_rs_succ*p_realiz_minsa | AG12: =IF(S12>0,AC12*P12/S12,0) | AH12: =IF(T12>0,AD12*P12/T12,0) | AI12: =IF(Q12>0,AE12*P12/Q12,0) | AJ12: =IF(R12>0,AF12*P12/R12,0) | AK12: =AC12+AD12+AE12*p_pwin_cen+AF12*p_pwin_cen*p_minsa_occ | AL12: =(AC12-AG12)+(AD12-AH12)+(AE12-AI12)*p_pwin_cen+(AF12-AJ12)*p_pwin_cen*p_minsa_occ | AM12: =IF(P12>0,E12*p_sup_idx*(1+p_pack)/P12,0) | AN12: =IF(AND(Y12=1,H12>0),H12*p_mkt*Q12*p_rs_succ,0)
A13: MBZ100 | B13: Mebendazol 100 mg tableta | C13: Primera ola | D13: 1 | E13: 0.0085 | F13: 0.0009 | G13: R: sin licitación india pública; precio al público de Jan Aushadhi INR 8.44 por 6 x0.42 = INR 0.59, x1.4; 3 cm3 | H13: 188514 | I13: 0.13 | J13: =179270*p_cc_w | K13: 0.13 | L13: 8000 | M13: 0.2188 | N13: 1714 | O13: 0.1753 | P13: =E13*p_sup_idx*(1+p_pack)+F13*p_log_mult | Q13: =I13*p_pf_cen | R13: =K13*p_pf_cen | S13: =M13*p_pf_dec | T13: =O13*p_pf_dec | U13: =IF(Q13>0,1-P13/Q13,-9) | V13: =IF(R13>0,1-P13/R13,-9) | W13: =IF(S13>0,1-P13/S13,-9) | X13: =IF(T13>0,1-P13/T13,-9) | Y13: =IF(AND($D13=1,H13>0,U13>=p_gm_cen),1,0) | Z13: =IF(AND($D13=1,J13>0,V13>=p_gm_cen),1,0) | AA13: =IF(AND($D13=1,L13>0,W13>=p_gm_dec),1,0) | AB13: =IF(AND($D13=1,N13>0,X13>=p_gm_dec),1,0) | AC13: =AA13*L13*p_mkt*S13*p_rs_succ*p_share_dec | AD13: =AB13*N13*p_mkt*T13*p_rs_succ*p_share_dec | AE13: =Y13*H13*p_mkt*Q13*p_rs_succ*p_realiz | AF13: =Z13*J13*p_mkt*R13*p_rs_succ*p_realiz_minsa | AG13: =IF(S13>0,AC13*P13/S13,0) | AH13: =IF(T13>0,AD13*P13/T13,0) | AI13: =IF(Q13>0,AE13*P13/Q13,0) | AJ13: =IF(R13>0,AF13*P13/R13,0) | AK13: =AC13+AD13+AE13*p_pwin_cen+AF13*p_pwin_cen*p_minsa_occ | AL13: =(AC13-AG13)+(AD13-AH13)+(AE13-AI13)*p_pwin_cen+(AF13-AJ13)*p_pwin_cen*p_minsa_occ | AM13: =IF(P13>0,E13*p_sup_idx*(1+p_pack)/P13,0) | AN13: =IF(AND(Y13=1,H13>0),H13*p_mkt*Q13*p_rs_succ,0)
A14: NYSSUS | B14: Nistatina 100,000 UI/ml suspensión, frasco 30 ml | C14: Primera ola | D14: 1 | E14: 0.42 | F14: 0.0555 | G14: R: sin precio indio público; se usa US$0.42 con UNICEF US$0.60 por 30 ml como techo; 185 cm3 | H14: 14898 | I14: 3.18 | J14: =18118*p_cc_w | K14: 3.39 | L14: 0 | M14: 0 | N14: 2142 | O14: 3.3201 | P14: =E14*p_sup_idx*(1+p_pack)+F14*p_log_mult | Q14: =I14*p_pf_cen | R14: =K14*p_pf_cen | S14: =M14*p_pf_dec | T14: =O14*p_pf_dec | U14: =IF(Q14>0,1-P14/Q14,-9) | V14: =IF(R14>0,1-P14/R14,-9) | W14: =IF(S14>0,1-P14/S14,-9) | X14: =IF(T14>0,1-P14/T14,-9) | Y14: =IF(AND($D14=1,H14>0,U14>=p_gm_cen),1,0) | Z14: =IF(AND($D14=1,J14>0,V14>=p_gm_cen),1,0) | AA14: =IF(AND($D14=1,L14>0,W14>=p_gm_dec),1,0) | AB14: =IF(AND($D14=1,N14>0,X14>=p_gm_dec),1,0) | AC14: =AA14*L14*p_mkt*S14*p_rs_succ*p_share_dec | AD14: =AB14*N14*p_mkt*T14*p_rs_succ*p_share_dec | AE14: =Y14*H14*p_mkt*Q14*p_rs_succ*p_realiz | AF14: =Z14*J14*p_mkt*R14*p_rs_succ*p_realiz_minsa | AG14: =IF(S14>0,AC14*P14/S14,0) | AH14: =IF(T14>0,AD14*P14/T14,0) | AI14: =IF(Q14>0,AE14*P14/Q14,0) | AJ14: =IF(R14>0,AF14*P14/R14,0) | AK14: =AC14+AD14+AE14*p_pwin_cen+AF14*p_pwin_cen*p_minsa_occ | AL14: =(AC14-AG14)+(AD14-AH14)+(AE14-AI14)*p_pwin_cen+(AF14-AJ14)*p_pwin_cen*p_minsa_occ | AM14: =IF(P14>0,E14*p_sup_idx*(1+p_pack)/P14,0) | AN14: =IF(AND(Y14=1,H14>0),H14*p_mkt*Q14*p_rs_succ,0)
A15: HCTCRM | B15: Hidrocortisona 1% crema, tubo 15 g | C15: Primera ola | D15: 1 | E15: 0.1988 | F15: 0.033 | G15: R: PMBI 2024-26 INR 13.72 por tubo x1.4; 110 cm3 | H15: 89267 | I15: 0.555 | J15: =44276*p_cc_w | K15: 0.58 | L15: 0 | M15: 0 | N15: 1564 | O15: 1.4679 | P15: =E15*p_sup_idx*(1+p_pack)+F15*p_log_mult | Q15: =I15*p_pf_cen | R15: =K15*p_pf_cen | S15: =M15*p_pf_dec | T15: =O15*p_pf_dec | U15: =IF(Q15>0,1-P15/Q15,-9) | V15: =IF(R15>0,1-P15/R15,-9) | W15: =IF(S15>0,1-P15/S15,-9) | X15: =IF(T15>0,1-P15/T15,-9) | Y15: =IF(AND($D15=1,H15>0,U15>=p_gm_cen),1,0) | Z15: =IF(AND($D15=1,J15>0,V15>=p_gm_cen),1,0) | AA15: =IF(AND($D15=1,L15>0,W15>=p_gm_dec),1,0) | AB15: =IF(AND($D15=1,N15>0,X15>=p_gm_dec),1,0) | AC15: =AA15*L15*p_mkt*S15*p_rs_succ*p_share_dec | AD15: =AB15*N15*p_mkt*T15*p_rs_succ*p_share_dec | AE15: =Y15*H15*p_mkt*Q15*p_rs_succ*p_realiz | AF15: =Z15*J15*p_mkt*R15*p_rs_succ*p_realiz_minsa | AG15: =IF(S15>0,AC15*P15/S15,0) | AH15: =IF(T15>0,AD15*P15/T15,0) | AI15: =IF(Q15>0,AE15*P15/Q15,0) | AJ15: =IF(R15>0,AF15*P15/R15,0) | AK15: =AC15+AD15+AE15*p_pwin_cen+AF15*p_pwin_cen*p_minsa_occ | AL15: =(AC15-AG15)+(AD15-AH15)+(AE15-AI15)*p_pwin_cen+(AF15-AJ15)*p_pwin_cen*p_minsa_occ | AM15: =IF(P15>0,E15*p_sup_idx*(1+p_pack)/P15,0) | AN15: =IF(AND(Y15=1,H15>0),H15*p_mkt*Q15*p_rs_succ,0)
A16: MOMCRM | B16: Mometasona 0.1% crema, tubo 15 g (renglón de corticoide de alta potencia) | C16: Primera ola | D16: 1 | E16: 0.1 | F16: 0.033 | G16: R: PMBI 2023-25 INR 6.00 por tubo; x1.4 = US$0.087; se usa 0.10; 110 cm3 | H16: 65534 | I16: 1.02 | J16: =34482*p_cc_w | K16: 0.65 | L16: 0 | M16: 0 | N16: 343 | O16: 3.66 | P16: =E16*p_sup_idx*(1+p_pack)+F16*p_log_mult | Q16: =I16*p_pf_cen | R16: =K16*p_pf_cen | S16: =M16*p_pf_dec | T16: =O16*p_pf_dec | U16: =IF(Q16>0,1-P16/Q16,-9) | V16: =IF(R16>0,1-P16/R16,-9) | W16: =IF(S16>0,1-P16/S16,-9) | X16: =IF(T16>0,1-P16/T16,-9) | Y16: =IF(AND($D16=1,H16>0,U16>=p_gm_cen),1,0) | Z16: =IF(AND($D16=1,J16>0,V16>=p_gm_cen),1,0) | AA16: =IF(AND($D16=1,L16>0,W16>=p_gm_dec),1,0) | AB16: =IF(AND($D16=1,N16>0,X16>=p_gm_dec),1,0) | AC16: =AA16*L16*p_mkt*S16*p_rs_succ*p_share_dec | AD16: =AB16*N16*p_mkt*T16*p_rs_succ*p_share_dec | AE16: =Y16*H16*p_mkt*Q16*p_rs_succ*p_realiz | AF16: =Z16*J16*p_mkt*R16*p_rs_succ*p_realiz_minsa | AG16: =IF(S16>0,AC16*P16/S16,0) | AH16: =IF(T16>0,AD16*P16/T16,0) | AI16: =IF(Q16>0,AE16*P16/Q16,0) | AJ16: =IF(R16>0,AF16*P16/R16,0) | AK16: =AC16+AD16+AE16*p_pwin_cen+AF16*p_pwin_cen*p_minsa_occ | AL16: =(AC16-AG16)+(AD16-AH16)+(AE16-AI16)*p_pwin_cen+(AF16-AJ16)*p_pwin_cen*p_minsa_occ | AM16: =IF(P16>0,E16*p_sup_idx*(1+p_pack)/P16,0) | AN16: =IF(AND(Y16=1,H16>0),H16*p_mkt*Q16*p_rs_succ,0)
A17: AMI10 | B17: Amitriptilina 10 mg tableta | C17: SNC | D17: 0 | E17: 0.0028 | F17: 0.00054 | G17: R: Assam 2025 INR 1.90 por 10 (PMBI INR 1.99; TNMSC INR 1.71), x1.4 | H17: 325776 | I17: 0.12 | J17: =152808*p_cc_w | K17: 0.12 | L17: 0 | M17: 0 | N17: 0 | O17: 0 | P17: =E17*p_sup_idx*(1+p_pack)+F17*p_log_mult | Q17: =I17*p_pf_cen | R17: =K17*p_pf_cen | S17: =M17*p_pf_dec | T17: =O17*p_pf_dec | U17: =IF(Q17>0,1-P17/Q17,-9) | V17: =IF(R17>0,1-P17/R17,-9) | W17: =IF(S17>0,1-P17/S17,-9) | X17: =IF(T17>0,1-P17/T17,-9) | Y17: =IF(AND($D17=1,H17>0,U17>=p_gm_cen),1,0) | Z17: =IF(AND($D17=1,J17>0,V17>=p_gm_cen),1,0) | AA17: =IF(AND($D17=1,L17>0,W17>=p_gm_dec),1,0) | AB17: =IF(AND($D17=1,N17>0,X17>=p_gm_dec),1,0) | AC17: =AA17*L17*p_mkt*S17*p_rs_succ*p_share_dec | AD17: =AB17*N17*p_mkt*T17*p_rs_succ*p_share_dec | AE17: =Y17*H17*p_mkt*Q17*p_rs_succ*p_realiz | AF17: =Z17*J17*p_mkt*R17*p_rs_succ*p_realiz_minsa | AG17: =IF(S17>0,AC17*P17/S17,0) | AH17: =IF(T17>0,AD17*P17/T17,0) | AI17: =IF(Q17>0,AE17*P17/Q17,0) | AJ17: =IF(R17>0,AF17*P17/R17,0) | AK17: =AC17+AD17+AE17*p_pwin_cen+AF17*p_pwin_cen*p_minsa_occ | AL17: =(AC17-AG17)+(AD17-AH17)+(AE17-AI17)*p_pwin_cen+(AF17-AJ17)*p_pwin_cen*p_minsa_occ | AM17: =IF(P17>0,E17*p_sup_idx*(1+p_pack)/P17,0) | AN17: =IF(AND(Y17=1,H17>0),H17*p_mkt*Q17*p_rs_succ,0)
A18: AMI25 | B18: Amitriptilina 25 mg tableta | C18: SNC | D18: 0 | E18: 0.0033 | F18: 0.00054 | G18: R: Assam 2025 INR 2.30 por 10 (TNMSC INR 19.63 por 100; PMBI INR 3.49 por 15), x1.4 | H18: 1953204 | I18: 0.027 | J18: 0 | K18: 0 | L18: 0 | M18: 0 | N18: 3086 | O18: 0.4 | P18: =E18*p_sup_idx*(1+p_pack)+F18*p_log_mult | Q18: =I18*p_pf_cen | R18: =K18*p_pf_cen | S18: =M18*p_pf_dec | T18: =O18*p_pf_dec | U18: =IF(Q18>0,1-P18/Q18,-9) | V18: =IF(R18>0,1-P18/R18,-9) | W18: =IF(S18>0,1-P18/S18,-9) | X18: =IF(T18>0,1-P18/T18,-9) | Y18: =IF(AND($D18=1,H18>0,U18>=p_gm_cen),1,0) | Z18: =IF(AND($D18=1,J18>0,V18>=p_gm_cen),1,0) | AA18: =IF(AND($D18=1,L18>0,W18>=p_gm_dec),1,0) | AB18: =IF(AND($D18=1,N18>0,X18>=p_gm_dec),1,0) | AC18: =AA18*L18*p_mkt*S18*p_rs_succ*p_share_dec | AD18: =AB18*N18*p_mkt*T18*p_rs_succ*p_share_dec | AE18: =Y18*H18*p_mkt*Q18*p_rs_succ*p_realiz | AF18: =Z18*J18*p_mkt*R18*p_rs_succ*p_realiz_minsa | AG18: =IF(S18>0,AC18*P18/S18,0) | AH18: =IF(T18>0,AD18*P18/T18,0) | AI18: =IF(Q18>0,AE18*P18/Q18,0) | AJ18: =IF(R18>0,AF18*P18/R18,0) | AK18: =AC18+AD18+AE18*p_pwin_cen+AF18*p_pwin_cen*p_minsa_occ | AL18: =(AC18-AG18)+(AD18-AH18)+(AE18-AI18)*p_pwin_cen+(AF18-AJ18)*p_pwin_cen*p_minsa_occ | AM18: =IF(P18>0,E18*p_sup_idx*(1+p_pack)/P18,0) | AN18: =IF(AND(Y18=1,H18>0),H18*p_mkt*Q18*p_rs_succ,0)
A19: QTP25 | B19: Quetiapina 25 mg tableta | C19: SNC | D19: 0 | E19: 0.0053 | F19: 0.00054 | G19: R: PMBI 2023-26 INR 3.69 por 10 x1.4 | H19: 0 | I19: 0 | J19: 0 | K19: 0 | L19: 0 | M19: 0 | N19: 558798 | O19: 0.18 | P19: =E19*p_sup_idx*(1+p_pack)+F19*p_log_mult | Q19: =I19*p_pf_cen | R19: =K19*p_pf_cen | S19: =M19*p_pf_dec | T19: =O19*p_pf_dec | U19: =IF(Q19>0,1-P19/Q19,-9) | V19: =IF(R19>0,1-P19/R19,-9) | W19: =IF(S19>0,1-P19/S19,-9) | X19: =IF(T19>0,1-P19/T19,-9) | Y19: =IF(AND($D19=1,H19>0,U19>=p_gm_cen),1,0) | Z19: =IF(AND($D19=1,J19>0,V19>=p_gm_cen),1,0) | AA19: =IF(AND($D19=1,L19>0,W19>=p_gm_dec),1,0) | AB19: =IF(AND($D19=1,N19>0,X19>=p_gm_dec),1,0) | AC19: =AA19*L19*p_mkt*S19*p_rs_succ*p_share_dec | AD19: =AB19*N19*p_mkt*T19*p_rs_succ*p_share_dec | AE19: =Y19*H19*p_mkt*Q19*p_rs_succ*p_realiz | AF19: =Z19*J19*p_mkt*R19*p_rs_succ*p_realiz_minsa | AG19: =IF(S19>0,AC19*P19/S19,0) | AH19: =IF(T19>0,AD19*P19/T19,0) | AI19: =IF(Q19>0,AE19*P19/Q19,0) | AJ19: =IF(R19>0,AF19*P19/R19,0) | AK19: =AC19+AD19+AE19*p_pwin_cen+AF19*p_pwin_cen*p_minsa_occ | AL19: =(AC19-AG19)+(AD19-AH19)+(AE19-AI19)*p_pwin_cen+(AF19-AJ19)*p_pwin_cen*p_minsa_occ | AM19: =IF(P19>0,E19*p_sup_idx*(1+p_pack)/P19,0) | AN19: =IF(AND(Y19=1,H19>0),H19*p_mkt*Q19*p_rs_succ,0)
A20: QTP100 | B20: Quetiapina 100 mg tableta | C20: SNC | D20: 0 | E20: 0.0138 | F20: 0.00066 | G20: R: interpolado de PMBI 25 y 200 mg x1.4 | H20: 0 | I20: 0 | J20: 0 | K20: 0 | L20: 0 | M20: 0 | N20: 509795 | O20: 0.13 | P20: =E20*p_sup_idx*(1+p_pack)+F20*p_log_mult | Q20: =I20*p_pf_cen | R20: =K20*p_pf_cen | S20: =M20*p_pf_dec | T20: =O20*p_pf_dec | U20: =IF(Q20>0,1-P20/Q20,-9) | V20: =IF(R20>0,1-P20/R20,-9) | W20: =IF(S20>0,1-P20/S20,-9) | X20: =IF(T20>0,1-P20/T20,-9) | Y20: =IF(AND($D20=1,H20>0,U20>=p_gm_cen),1,0) | Z20: =IF(AND($D20=1,J20>0,V20>=p_gm_cen),1,0) | AA20: =IF(AND($D20=1,L20>0,W20>=p_gm_dec),1,0) | AB20: =IF(AND($D20=1,N20>0,X20>=p_gm_dec),1,0) | AC20: =AA20*L20*p_mkt*S20*p_rs_succ*p_share_dec | AD20: =AB20*N20*p_mkt*T20*p_rs_succ*p_share_dec | AE20: =Y20*H20*p_mkt*Q20*p_rs_succ*p_realiz | AF20: =Z20*J20*p_mkt*R20*p_rs_succ*p_realiz_minsa | AG20: =IF(S20>0,AC20*P20/S20,0) | AH20: =IF(T20>0,AD20*P20/T20,0) | AI20: =IF(Q20>0,AE20*P20/Q20,0) | AJ20: =IF(R20>0,AF20*P20/R20,0) | AK20: =AC20+AD20+AE20*p_pwin_cen+AF20*p_pwin_cen*p_minsa_occ | AL20: =(AC20-AG20)+(AD20-AH20)+(AE20-AI20)*p_pwin_cen+(AF20-AJ20)*p_pwin_cen*p_minsa_occ | AM20: =IF(P20>0,E20*p_sup_idx*(1+p_pack)/P20,0) | AN20: =IF(AND(Y20=1,H20>0),H20*p_mkt*Q20*p_rs_succ,0)
A21: QTP200 | B21: Quetiapina 200 mg tableta | C21: SNC | D21: 0 | E21: 0.0216 | F21: 0.00075 | G21: R: PMBI 2023-25 INR 14.90 por 10 x1.4 | H21: 1376100 | I21: 0.079 | J21: 0 | K21: 0 | L21: 243829 | M21: 0.21 | N21: 28886 | O21: 0.2 | P21: =E21*p_sup_idx*(1+p_pack)+F21*p_log_mult | Q21: =I21*p_pf_cen | R21: =K21*p_pf_cen | S21: =M21*p_pf_dec | T21: =O21*p_pf_dec | U21: =IF(Q21>0,1-P21/Q21,-9) | V21: =IF(R21>0,1-P21/R21,-9) | W21: =IF(S21>0,1-P21/S21,-9) | X21: =IF(T21>0,1-P21/T21,-9) | Y21: =IF(AND($D21=1,H21>0,U21>=p_gm_cen),1,0) | Z21: =IF(AND($D21=1,J21>0,V21>=p_gm_cen),1,0) | AA21: =IF(AND($D21=1,L21>0,W21>=p_gm_dec),1,0) | AB21: =IF(AND($D21=1,N21>0,X21>=p_gm_dec),1,0) | AC21: =AA21*L21*p_mkt*S21*p_rs_succ*p_share_dec | AD21: =AB21*N21*p_mkt*T21*p_rs_succ*p_share_dec | AE21: =Y21*H21*p_mkt*Q21*p_rs_succ*p_realiz | AF21: =Z21*J21*p_mkt*R21*p_rs_succ*p_realiz_minsa | AG21: =IF(S21>0,AC21*P21/S21,0) | AH21: =IF(T21>0,AD21*P21/T21,0) | AI21: =IF(Q21>0,AE21*P21/Q21,0) | AJ21: =IF(R21>0,AF21*P21/R21,0) | AK21: =AC21+AD21+AE21*p_pwin_cen+AF21*p_pwin_cen*p_minsa_occ | AL21: =(AC21-AG21)+(AD21-AH21)+(AE21-AI21)*p_pwin_cen+(AF21-AJ21)*p_pwin_cen*p_minsa_occ | AM21: =IF(P21>0,E21*p_sup_idx*(1+p_pack)/P21,0) | AN21: =IF(AND(Y21=1,H21>0),H21*p_mkt*Q21*p_rs_succ,0)
A22: TPM100 | B22: Topiramato 100 mg tableta | C22: SNC | D22: 0 | E22: 0.0116 | F22: 0.0006 | G22: R: PMBI 2023-25 INR 7.98 por 10 x1.4 | H22: 443907 | I22: 0.065 | J22: 0 | K22: 0 | L22: 26343 | M22: 1.02 | N22: 4640 | O22: 1.18 | P22: =E22*p_sup_idx*(1+p_pack)+F22*p_log_mult | Q22: =I22*p_pf_cen | R22: =K22*p_pf_cen | S22: =M22*p_pf_dec | T22: =O22*p_pf_dec | U22: =IF(Q22>0,1-P22/Q22,-9) | V22: =IF(R22>0,1-P22/R22,-9) | W22: =IF(S22>0,1-P22/S22,-9) | X22: =IF(T22>0,1-P22/T22,-9) | Y22: =IF(AND($D22=1,H22>0,U22>=p_gm_cen),1,0) | Z22: =IF(AND($D22=1,J22>0,V22>=p_gm_cen),1,0) | AA22: =IF(AND($D22=1,L22>0,W22>=p_gm_dec),1,0) | AB22: =IF(AND($D22=1,N22>0,X22>=p_gm_dec),1,0) | AC22: =AA22*L22*p_mkt*S22*p_rs_succ*p_share_dec | AD22: =AB22*N22*p_mkt*T22*p_rs_succ*p_share_dec | AE22: =Y22*H22*p_mkt*Q22*p_rs_succ*p_realiz | AF22: =Z22*J22*p_mkt*R22*p_rs_succ*p_realiz_minsa | AG22: =IF(S22>0,AC22*P22/S22,0) | AH22: =IF(T22>0,AD22*P22/T22,0) | AI22: =IF(Q22>0,AE22*P22/Q22,0) | AJ22: =IF(R22>0,AF22*P22/R22,0) | AK22: =AC22+AD22+AE22*p_pwin_cen+AF22*p_pwin_cen*p_minsa_occ | AL22: =(AC22-AG22)+(AD22-AH22)+(AE22-AI22)*p_pwin_cen+(AF22-AJ22)*p_pwin_cen*p_minsa_occ | AM22: =IF(P22>0,E22*p_sup_idx*(1+p_pack)/P22,0) | AN22: =IF(AND(Y22=1,H22>0),H22*p_mkt*Q22*p_rs_succ,0)
B23: Totales (productos incluidos) | AC23: =SUM(AC6:AC22) | AD23: =SUM(AD6:AD22) | AE23: =SUM(AE6:AE22) | AF23: =SUM(AF6:AF22) | AG23: =SUM(AG6:AG22) | AH23: =SUM(AH6:AH22) | AI23: =SUM(AI6:AI22) | AJ23: =SUM(AJ6:AJ22) | ... AL23: =SUM(AL6:AL22) | AM23: =IF(SUM(AG6:AJ22)>0,SUMPRODUCT(AG6:AG22+AH6:AH22+AI6:AI22+AJ6:AJ22,AM6:AM22)/SUM(AG6:AJ22),0) | AN23: =SUM(AN6:AN22)

Sheet Mensual
A1: Flujo mensual (B/.)
C2: Mes 0
A3: Mes | C3: 0 | D3: 1 | E3: 2 | F3: 3 | G3: 4 | H3: 5 | I3: 6 | J3: 7 | K3: 8 | L3: 9 | M3: 10 | N3: 11 | O3: 12 | P3: 13 | Q3: 14 | R3: 15 | S3: 16 | T3: 17 | U3: 18 | V3: 19 | W3: 20 | X3: 21 | Y3: 22 | Z3: 23 | AA3: 24 | AB3: 25 | AC3: 26 | AD3: 27 | AE3: 28 | AF3: 29 | AG3: 30 | AH3: 31 | AI3: 32 | AJ3: 33 | AK3: 34 | AL3: 35 | AM3: 36 | AN3: 37 | AO3: 38 | AP3: 39 | AQ3: 40 | AR3: 41 | AS3: 42 | AT3: 43 | AU3: 44 | AV3: 45 | AW3: 46 | AX3: 47 | AY3: 48 | AZ3: 49 | BA3: 50 | BB3: 51 | BC3: 52 | BD3: 53 | BE3: 54 | BF3: 55 | BG3: 56 | BH3: 57 | BI3: 58 | BJ3: 59 | BK3: 60 | BL3: 61
A4: Año | D4: =INT((MIN(D$3,60)-1)/12)+1 | E4: =INT((MIN(E$3,60)-1)/12)+1 | F4: =INT((MIN(F$3,60)-1)/12)+1 | G4: =INT((MIN(G$3,60)-1)/12)+1 | H4: =INT((MIN(H$3,60)-1)/12)+1 | I4: =INT((MIN(I$3,60)-1)/12)+1 | J4: =INT((MIN(J$3,60)-1)/12)+1 | K4: =INT((MIN(K$3,60)-1)/12)+1 | ... BL4: =INT((MIN(BL$3,60)-1)/12)+1
A5: Factor de erosión de precios | D5: =(1-p_erosion)^(D4-1) | E5: =(1-p_erosion)^(E4-1) | F5: =(1-p_erosion)^(F4-1) | G5: =(1-p_erosion)^(G4-1) | H5: =(1-p_erosion)^(H4-1) | I5: =(1-p_erosion)^(I4-1) | J5: =(1-p_erosion)^(J4-1) | K5: =(1-p_erosion)^(K4-1) | ... BL5: =(1-p_erosion)^(BL4-1)
A6: Negocio activo (1/0) | D6: =IF(D$3<=ROUND(p_stop_det,0),1,0) | E6: =IF(E$3<=ROUND(p_stop_det,0),1,0) | F6: =IF(F$3<=ROUND(p_stop_det,0),1,0) | G6: =IF(G$3<=ROUND(p_stop_det,0),1,0) | H6: =IF(H$3<=ROUND(p_stop_det,0),1,0) | I6: =IF(I$3<=ROUND(p_stop_det,0),1,0) | J6: =IF(J$3<=ROUND(p_stop_det,0),1,0) | K6: =IF(K$3<=ROUND(p_stop_det,0),1,0) | ... BL6: =IF(BL$3<=ROUND(p_stop_det,0),1,0)
A7: Rampa primera ola | D7: =MAX(0,MIN(1,(D$3-c_first_dec+1)/p_ramp_m)) | E7: =MAX(0,MIN(1,(E$3-c_first_dec+1)/p_ramp_m)) | F7: =MAX(0,MIN(1,(F$3-c_first_dec+1)/p_ramp_m)) | G7: =MAX(0,MIN(1,(G$3-c_first_dec+1)/p_ramp_m)) | H7: =MAX(0,MIN(1,(H$3-c_first_dec+1)/p_ramp_m)) | I7: =MAX(0,MIN(1,(I$3-c_first_dec+1)/p_ramp_m)) | J7: =MAX(0,MIN(1,(J$3-c_first_dec+1)/p_ramp_m)) | K7: =MAX(0,MIN(1,(K$3-c_first_dec+1)/p_ramp_m)) | ... BL7: =MAX(0,MIN(1,(BL$3-c_first_dec+1)/p_ramp_m))
A8: Rampa segunda ola | D8: =MAX(0,MIN(1,(D$3-c_first_dec2+1)/p_ramp_m)) | E8: =MAX(0,MIN(1,(E$3-c_first_dec2+1)/p_ramp_m)) | F8: =MAX(0,MIN(1,(F$3-c_first_dec2+1)/p_ramp_m)) | G8: =MAX(0,MIN(1,(G$3-c_first_dec2+1)/p_ramp_m)) | H8: =MAX(0,MIN(1,(H$3-c_first_dec2+1)/p_ramp_m)) | I8: =MAX(0,MIN(1,(I$3-c_first_dec2+1)/p_ramp_m)) | J8: =MAX(0,MIN(1,(J$3-c_first_dec2+1)/p_ramp_m)) | K8: =MAX(0,MIN(1,(K$3-c_first_dec2+1)/p_ramp_m)) | ... BL8: =MAX(0,MIN(1,(BL$3-c_first_dec2+1)/p_ramp_m))
A9: Contratos centralizados activos | D9: =IF(D$3>=c_cen_start,1,0) | E9: =IF(E$3>=c_cen_start,1,0) | F9: =IF(F$3>=c_cen_start,1,0) | G9: =IF(G$3>=c_cen_start,1,0) | H9: =IF(H$3>=c_cen_start,1,0) | I9: =IF(I$3>=c_cen_start,1,0) | J9: =IF(J$3>=c_cen_start,1,0) | K9: =IF(K$3>=c_cen_start,1,0) | ... BL9: =IF(BL$3>=c_cen_start,1,0)
A10: LPU con segunda ola | D10: =IF(D$3>=c_c2_lpu,1,0) | E10: =IF(E$3>=c_c2_lpu,1,0) | F10: =IF(F$3>=c_c2_lpu,1,0) | G10: =IF(G$3>=c_c2_lpu,1,0) | H10: =IF(H$3>=c_c2_lpu,1,0) | I10: =IF(I$3>=c_c2_lpu,1,0) | J10: =IF(J$3>=c_c2_lpu,1,0) | K10: =IF(K$3>=c_c2_lpu,1,0) | ... BL10: =IF(BL$3>=c_c2_lpu,1,0)
A11: MINSA central con segunda ola | D11: =IF(D$3>=c_c2_minsa,1,0) | E11: =IF(E$3>=c_c2_minsa,1,0) | F11: =IF(F$3>=c_c2_minsa,1,0) | G11: =IF(G$3>=c_c2_minsa,1,0) | H11: =IF(H$3>=c_c2_minsa,1,0) | I11: =IF(I$3>=c_c2_minsa,1,0) | J11: =IF(J$3>=c_c2_minsa,1,0) | K11: =IF(K$3>=c_c2_minsa,1,0) | ... BL11: =IF(BL$3>=c_c2_minsa,1,0)
A12: Multiplicador descentralizado (olas) | D12: =1+c_k2*D8 | E12: =1+c_k2*E8 | F12: =1+c_k2*F8 | G12: =1+c_k2*G8 | H12: =1+c_k2*H8 | I12: =1+c_k2*I8 | J12: =1+c_k2*J8 | K12: =1+c_k2*K8 | ... BL12: =1+c_k2*BL8
A13: Multiplicador LPU (olas) | D13: =1+c_k2*D10 | E13: =1+c_k2*E10 | F13: =1+c_k2*F10 | G13: =1+c_k2*G10 | H13: =1+c_k2*H10 | I13: =1+c_k2*I10 | J13: =1+c_k2*J10 | K13: =1+c_k2*K10 | ... BL13: =1+c_k2*BL10
A14: Multiplicador MINSA central (olas) | D14: =1+c_k2*D11 | E14: =1+c_k2*E11 | F14: =1+c_k2*F11 | G14: =1+c_k2*G11 | H14: =1+c_k2*H11 | I14: =1+c_k2*I11 | J14: =1+c_k2*J11 | K14: =1+c_k2*K11 | ... BL14: =1+c_k2*BL11
A15: Ventas descentralizadas | D15: =(s_Rd3+s_Rd4)/12*D7*D12*D5*D6 | E15: =(s_Rd3+s_Rd4)/12*E7*E12*E5*E6 | F15: =(s_Rd3+s_Rd4)/12*F7*F12*F5*F6 | G15: =(s_Rd3+s_Rd4)/12*G7*G12*G5*G6 | H15: =(s_Rd3+s_Rd4)/12*H7*H12*H5*H6 | I15: =(s_Rd3+s_Rd4)/12*I7*I12*I5*I6 | J15: =(s_Rd3+s_Rd4)/12*J7*J12*J5*J6 | K15: =(s_Rd3+s_Rd4)/12*K7*K12*K5*K6 | ... BL15: =(s_Rd3+s_Rd4)/12*BL7*BL12*BL5*BL6
A16: Ventas centralizadas | D16: =(s_Rc1*p_pwin_cen*D13+s_Rc2*p_pwin_cen*p_minsa_occ*D14)/12*D9*D5*D6 | E16: =(s_Rc1*p_pwin_cen*E13+s_Rc2*p_pwin_cen*p_minsa_occ*E14)/12*E9*E5*E6 | F16: =(s_Rc1*p_pwin_cen*F13+s_Rc2*p_pwin_cen*p_minsa_occ*F14)/12*F9*F5*F6 | G16: =(s_Rc1*p_pwin_cen*G13+s_Rc2*p_pwin_cen*p_minsa_occ*G14)/12*G9*G5*G6 | H16: =(s_Rc1*p_pwin_cen*H13+s_Rc2*p_pwin_cen*p_minsa_occ*H14)/12*H9*H5*H6 | I16: =(s_Rc1*p_pwin_cen*I13+s_Rc2*p_pwin_cen*p_minsa_occ*I14)/12*I9*I5*I6 | J16: =(s_Rc1*p_pwin_cen*J13+s_Rc2*p_pwin_cen*p_minsa_occ*J14)/12*J9*J5*J6 | K16: =(s_Rc1*p_pwin_cen*K13+s_Rc2*p_pwin_cen*p_minsa_occ*K14)/12*K9*K5*K6 | ... BL16: =(s_Rc1*p_pwin_cen*BL13+s_Rc2*p_pwin_cen*p_minsa_occ*BL14)/12*BL9*BL5*BL6
A17: VENTAS TOTALES | D17: =D15+D16 | E17: =E15+E16 | F17: =F15+F16 | G17: =G15+G16 | H17: =H15+H16 | I17: =I15+I16 | J17: =J15+J16 | K17: =K15+K16 | ... BL17: =BL15+BL16
A18: Costo de ventas descentralizado | D18: =(s_Rd3k+s_Rd4k)/12*D7*D12*D6 | E18: =(s_Rd3k+s_Rd4k)/12*E7*E12*E6 | F18: =(s_Rd3k+s_Rd4k)/12*F7*F12*F6 | G18: =(s_Rd3k+s_Rd4k)/12*G7*G12*G6 | H18: =(s_Rd3k+s_Rd4k)/12*H7*H12*H6 | I18: =(s_Rd3k+s_Rd4k)/12*I7*I12*I6 | J18: =(s_Rd3k+s_Rd4k)/12*J7*J12*J6 | K18: =(s_Rd3k+s_Rd4k)/12*K7*K12*K6 | ... BL18: =(s_Rd3k+s_Rd4k)/12*BL7*BL12*BL6
A19: Costo de ventas centralizado | D19: =(s_Rc1k*p_pwin_cen*D13+s_Rc2k*p_pwin_cen*p_minsa_occ*D14)/12*D9*D6 | E19: =(s_Rc1k*p_pwin_cen*E13+s_Rc2k*p_pwin_cen*p_minsa_occ*E14)/12*E9*E6 | F19: =(s_Rc1k*p_pwin_cen*F13+s_Rc2k*p_pwin_cen*p_minsa_occ*F14)/12*F9*F6 | G19: =(s_Rc1k*p_pwin_cen*G13+s_Rc2k*p_pwin_cen*p_minsa_occ*G14)/12*G9*G6 | H19: =(s_Rc1k*p_pwin_cen*H13+s_Rc2k*p_pwin_cen*p_minsa_occ*H14)/12*H9*H6 | I19: =(s_Rc1k*p_pwin_cen*I13+s_Rc2k*p_pwin_cen*p_minsa_occ*I14)/12*I9*I6 | J19: =(s_Rc1k*p_pwin_cen*J13+s_Rc2k*p_pwin_cen*p_minsa_occ*J14)/12*J9*J6 | K19: =(s_Rc1k*p_pwin_cen*K13+s_Rc2k*p_pwin_cen*p_minsa_occ*K14)/12*K9*K6 | ... BL19: =(s_Rc1k*p_pwin_cen*BL13+s_Rc2k*p_pwin_cen*p_minsa_occ*BL14)/12*BL9*BL6
A20: COSTO DE VENTAS | D20: =D18+D19 | E20: =E18+E19 | F20: =F18+F19 | G20: =G18+G19 | H20: =H18+H19 | I20: =I18+I19 | J20: =J18+J19 | K20: =K18+K19 | ... BL20: =BL18+BL19
A21: Inventario objetivo al cierre (costo) | C21: 0 | D21: =IF(AND(D$3>=c_first_dec,D$3<=ROUND(p_stop_det,0)),(s_Rd3k+s_Rd4k)/12*E7*E12*p_cover_m+(s_Rc1k*p_pwin_cen*E13+s_Rc2k*p_pwin_cen*p_minsa_occ*E14)/12*E9*p_cen_stock_m,0) | E21: =IF(AND(E$3>=c_first_dec,E$3<=ROUND(p_stop_det,0)),(s_Rd3k+s_Rd4k)/12*F7*F12*p_cover_m+(s_Rc1k*p_pwin_cen*F13+s_Rc2k*p_pwin_cen*p_minsa_occ*F14)/12*F9*p_cen_stock_m,0) | F21: =IF(AND(F$3>=c_first_dec,F$3<=ROUND(p_stop_det,0)),(s_Rd3k+s_Rd4k)/12*G7*G12*p_cover_m+(s_Rc1k*p_pwin_cen*G13+s_Rc2k*p_pwin_cen*p_minsa_occ*G14)/12*G9*p_cen_stock_m,0) | G21: =IF(AND(G$3>=c_first_dec,G$3<=ROUND(p_stop_det,0)),(s_Rd3k+s_Rd4k)/12*H7*H12*p_cover_m+(s_Rc1k*p_pwin_cen*H13+s_Rc2k*p_pwin_cen*p_minsa_occ*H14)/12*H9*p_cen_stock_m,0) | H21: =IF(AND(H$3>=c_first_dec,H$3<=ROUND(p_stop_det,0)),(s_Rd3k+s_Rd4k)/12*I7*I12*p_cover_m+(s_Rc1k*p_pwin_cen*I13+s_Rc2k*p_pwin_cen*p_minsa_occ*I14)/12*I9*p_cen_stock_m,0) | I21: =IF(AND(I$3>=c_first_dec,I$3<=ROUND(p_stop_det,0)),(s_Rd3k+s_Rd4k)/12*J7*J12*p_cover_m+(s_Rc1k*p_pwin_cen*J13+s_Rc2k*p_pwin_cen*p_minsa_occ*J14)/12*J9*p_cen_stock_m,0) | J21: =IF(AND(J$3>=c_first_dec,J$3<=ROUND(p_stop_det,0)),(s_Rd3k+s_Rd4k)/12*K7*K12*p_cover_m+(s_Rc1k*p_pwin_cen*K13+s_Rc2k*p_pwin_cen*p_minsa_occ*K14)/12*K9*p_cen_stock_m,0) | K21: =IF(AND(K$3>=c_first_dec,K$3<=ROUND(p_stop_det,0)),(s_Rd3k+s_Rd4k)/12*L7*L12*p_cover_m+(s_Rc1k*p_pwin_cen*L13+s_Rc2k*p_pwin_cen*p_minsa_occ*L14)/12*L9*p_cen_stock_m,0) | ... BK21: =IF(AND(BK$3>=c_first_dec,BK$3<=ROUND(p_stop_det,0)),(s_Rd3k+s_Rd4k)/12*BL7*BL12*p_cover_m+(s_Rc1k*p_pwin_cen*BL13+s_Rc2k*p_pwin_cen*p_minsa_occ*BL14)/12*BL9*p_cen_stock_m,0)
A22: Mercancía recibida (costo, incl. mermas) | D22: =IF(D$3>ROUND(p_stop_det,0),0,D20*(1+p_expiry)+D21-C21) | E22: =IF(E$3>ROUND(p_stop_det,0),0,E20*(1+p_expiry)+E21-D21) | F22: =IF(F$3>ROUND(p_stop_det,0),0,F20*(1+p_expiry)+F21-E21) | G22: =IF(G$3>ROUND(p_stop_det,0),0,G20*(1+p_expiry)+G21-F21) | H22: =IF(H$3>ROUND(p_stop_det,0),0,H20*(1+p_expiry)+H21-G21) | I22: =IF(I$3>ROUND(p_stop_det,0),0,I20*(1+p_expiry)+I21-H21) | J22: =IF(J$3>ROUND(p_stop_det,0),0,J20*(1+p_expiry)+J21-I21) | K22: =IF(K$3>ROUND(p_stop_det,0),0,K20*(1+p_expiry)+K21-J21) | ... BK22: =IF(BK$3>ROUND(p_stop_det,0),0,BK20*(1+p_expiry)+BK21-BJ21)
A23: Pago de anticipos al proveedor | D23: =p_adv*IFERROR(INDEX($D$22:$BK$22,1,D$3+c_lead_m),0) | E23: =p_adv*IFERROR(INDEX($D$22:$BK$22,1,E$3+c_lead_m),0) | F23: =p_adv*IFERROR(INDEX($D$22:$BK$22,1,F$3+c_lead_m),0) | G23: =p_adv*IFERROR(INDEX($D$22:$BK$22,1,G$3+c_lead_m),0) | H23: =p_adv*IFERROR(INDEX($D$22:$BK$22,1,H$3+c_lead_m),0) | I23: =p_adv*IFERROR(INDEX($D$22:$BK$22,1,I$3+c_lead_m),0) | J23: =p_adv*IFERROR(INDEX($D$22:$BK$22,1,J$3+c_lead_m),0) | K23: =p_adv*IFERROR(INDEX($D$22:$BK$22,1,K$3+c_lead_m),0) | ... BK23: =p_adv*IFERROR(INDEX($D$22:$BK$22,1,BK$3+c_lead_m),0)
A24: Pago de saldos al proveedor | D24: =IF(AND(D$3+c_ship_m-c_credit_m>=1,D$3+c_ship_m-c_credit_m<=60),(1-p_adv)*INDEX($D$22:$BK$22,1,D$3+c_ship_m-c_credit_m),0) | E24: =IF(AND(E$3+c_ship_m-c_credit_m>=1,E$3+c_ship_m-c_credit_m<=60),(1-p_adv)*INDEX($D$22:$BK$22,1,E$3+c_ship_m-c_credit_m),0) | F24: =IF(AND(F$3+c_ship_m-c_credit_m>=1,F$3+c_ship_m-c_credit_m<=60),(1-p_adv)*INDEX($D$22:$BK$22,1,F$3+c_ship_m-c_credit_m),0) | G24: =IF(AND(G$3+c_ship_m-c_credit_m>=1,G$3+c_ship_m-c_credit_m<=60),(1-p_adv)*INDEX($D$22:$BK$22,1,G$3+c_ship_m-c_credit_m),0) | H24: =IF(AND(H$3+c_ship_m-c_credit_m>=1,H$3+c_ship_m-c_credit_m<=60),(1-p_adv)*INDEX($D$22:$BK$22,1,H$3+c_ship_m-c_credit_m),0) | I24: =IF(AND(I$3+c_ship_m-c_credit_m>=1,I$3+c_ship_m-c_credit_m<=60),(1-p_adv)*INDEX($D$22:$BK$22,1,I$3+c_ship_m-c_credit_m),0) | J24: =IF(AND(J$3+c_ship_m-c_credit_m>=1,J$3+c_ship_m-c_credit_m<=60),(1-p_adv)*INDEX($D$22:$BK$22,1,J$3+c_ship_m-c_credit_m),0) | K24: =IF(AND(K$3+c_ship_m-c_credit_m>=1,K$3+c_ship_m-c_credit_m<=60),(1-p_adv)*INDEX($D$22:$BK$22,1,K$3+c_ship_m-c_credit_m),0) | ... BK24: =IF(AND(BK$3+c_ship_m-c_credit_m>=1,BK$3+c_ship_m-c_credit_m<=60),(1-p_adv)*INDEX($D$22:$BK$22,1,BK$3+c_ship_m-c_credit_m),0)
A25: PAGOS AL PROVEEDOR | D25: =D23+D24 | E25: =E23+E24 | F25: =F23+F24 | G25: =G23+G24 | H25: =H23+H24 | I25: =I23+I24 | J25: =J23+J24 | K25: =K23+K24 | ... BK25: =BK23+BK24
A26: COBRANZA (incl. liquidación de inventario al cierre) | D26: =(1-p_fact_share)*IF(D$3-c_dso_m>=1,INDEX($D$17:$BK$17,1,D$3-c_dso_m),0)*(1-p_baddebt)+p_fact_share*IF(D$3-1>=1,INDEX($D$17:$BK$17,1,D$3-1),0)*(1-p_baddebt)*(1-p_fact_cost*c_dso_m)+IF(D$3=ROUND(p_stop_det,0)+1,INDEX($D$21:$BK$21,1,ROUND(p_stop_det,0))*p_inv_liq,0) | E26: =(1-p_fact_share)*IF(E$3-c_dso_m>=1,INDEX($D$17:$BK$17,1,E$3-c_dso_m),0)*(1-p_baddebt)+p_fact_share*IF(E$3-1>=1,INDEX($D$17:$BK$17,1,E$3-1),0)*(1-p_baddebt)*(1-p_fact_cost*c_dso_m)+IF(E$3=ROUND(p_stop_det,0)+1,INDEX($D$21:$BK$21,1,ROUND(p_stop_det,0))*p_inv_liq,0) | F26: =(1-p_fact_share)*IF(F$3-c_dso_m>=1,INDEX($D$17:$BK$17,1,F$3-c_dso_m),0)*(1-p_baddebt)+p_fact_share*IF(F$3-1>=1,INDEX($D$17:$BK$17,1,F$3-1),0)*(1-p_baddebt)*(1-p_fact_cost*c_dso_m)+IF(F$3=ROUND(p_stop_det,0)+1,INDEX($D$21:$BK$21,1,ROUND(p_stop_det,0))*p_inv_liq,0) | G26: =(1-p_fact_share)*IF(G$3-c_dso_m>=1,INDEX($D$17:$BK$17,1,G$3-c_dso_m),0)*(1-p_baddebt)+p_fact_share*IF(G$3-1>=1,INDEX($D$17:$BK$17,1,G$3-1),0)*(1-p_baddebt)*(1-p_fact_cost*c_dso_m)+IF(G$3=ROUND(p_stop_det,0)+1,INDEX($D$21:$BK$21,1,ROUND(p_stop_det,0))*p_inv_liq,0) | H26: =(1-p_fact_share)*IF(H$3-c_dso_m>=1,INDEX($D$17:$BK$17,1,H$3-c_dso_m),0)*(1-p_baddebt)+p_fact_share*IF(H$3-1>=1,INDEX($D$17:$BK$17,1,H$3-1),0)*(1-p_baddebt)*(1-p_fact_cost*c_dso_m)+IF(H$3=ROUND(p_stop_det,0)+1,INDEX($D$21:$BK$21,1,ROUND(p_stop_det,0))*p_inv_liq,0) | I26: =(1-p_fact_share)*IF(I$3-c_dso_m>=1,INDEX($D$17:$BK$17,1,I$3-c_dso_m),0)*(1-p_baddebt)+p_fact_share*IF(I$3-1>=1,INDEX($D$17:$BK$17,1,I$3-1),0)*(1-p_baddebt)*(1-p_fact_cost*c_dso_m)+IF(I$3=ROUND(p_stop_det,0)+1,INDEX($D$21:$BK$21,1,ROUND(p_stop_det,0))*p_inv_liq,0) | J26: =(1-p_fact_share)*IF(J$3-c_dso_m>=1,INDEX($D$17:$BK$17,1,J$3-c_dso_m),0)*(1-p_baddebt)+p_fact_share*IF(J$3-1>=1,INDEX($D$17:$BK$17,1,J$3-1),0)*(1-p_baddebt)*(1-p_fact_cost*c_dso_m)+IF(J$3=ROUND(p_stop_det,0)+1,INDEX($D$21:$BK$21,1,ROUND(p_stop_det,0))*p_inv_liq,0) | K26: =(1-p_fact_share)*IF(K$3-c_dso_m>=1,INDEX($D$17:$BK$17,1,K$3-c_dso_m),0)*(1-p_baddebt)+p_fact_share*IF(K$3-1>=1,INDEX($D$17:$BK$17,1,K$3-1),0)*(1-p_baddebt)*(1-p_fact_cost*c_dso_m)+IF(K$3=ROUND(p_stop_det,0)+1,INDEX($D$21:$BK$21,1,ROUND(p_stop_det,0))*p_inv_liq,0) | ... BK26: =(1-p_fact_share)*IF(BK$3-c_dso_m>=1,INDEX($D$17:$BK$17,1,BK$3-c_dso_m),0)*(1-p_baddebt)+p_fact_share*IF(BK$3-1>=1,INDEX($D$17:$BK$17,1,BK$3-1),0)*(1-p_baddebt)*(1-p_fact_cost*c_dso_m)+IF(BK$3=ROUND(p_stop_det,0)+1,INDEX($D$21:$BK$21,1,ROUND(p_stop_det,0))*p_inv_liq,0)
A27: Gastos variables (distribución y multas) | D27: =(p_dist+p_penal)*D17 | E27: =(p_dist+p_penal)*E17 | F27: =(p_dist+p_penal)*F17 | G27: =(p_dist+p_penal)*G17 | H27: =(p_dist+p_penal)*H17 | I27: =(p_dist+p_penal)*I17 | J27: =(p_dist+p_penal)*J17 | K27: =(p_dist+p_penal)*K17 | ... BK27: =(p_dist+p_penal)*BK17
A28: Costos fijos | D28: =IF(D$3>ROUND(p_stop_det,0)+3,0,SUMPRODUCT(f_used*(D$3>=f_start))) | E28: =IF(E$3>ROUND(p_stop_det,0)+3,0,SUMPRODUCT(f_used*(E$3>=f_start))) | F28: =IF(F$3>ROUND(p_stop_det,0)+3,0,SUMPRODUCT(f_used*(F$3>=f_start))) | G28: =IF(G$3>ROUND(p_stop_det,0)+3,0,SUMPRODUCT(f_used*(G$3>=f_start))) | H28: =IF(H$3>ROUND(p_stop_det,0)+3,0,SUMPRODUCT(f_used*(H$3>=f_start))) | I28: =IF(I$3>ROUND(p_stop_det,0)+3,0,SUMPRODUCT(f_used*(I$3>=f_start))) | J28: =IF(J$3>ROUND(p_stop_det,0)+3,0,SUMPRODUCT(f_used*(J$3>=f_start))) | K28: =IF(K$3>ROUND(p_stop_det,0)+3,0,SUMPRODUCT(f_used*(K$3>=f_start))) | ... BK28: =IF(BK$3>ROUND(p_stop_det,0)+3,0,SUMPRODUCT(f_used*(BK$3>=f_start)))
A29: Análisis posregistro | D29: =IF(D$3>ROUND(p_stop_det,0)+3,0,c_n_reg1*p_postreg/12*IF(D$3>=c_reg_m,1,0)+c_n_reg2*p_postreg/12*IF(D$3>=c_m2+c_rt,1,0)) | E29: =IF(E$3>ROUND(p_stop_det,0)+3,0,c_n_reg1*p_postreg/12*IF(E$3>=c_reg_m,1,0)+c_n_reg2*p_postreg/12*IF(E$3>=c_m2+c_rt,1,0)) | F29: =IF(F$3>ROUND(p_stop_det,0)+3,0,c_n_reg1*p_postreg/12*IF(F$3>=c_reg_m,1,0)+c_n_reg2*p_postreg/12*IF(F$3>=c_m2+c_rt,1,0)) | G29: =IF(G$3>ROUND(p_stop_det,0)+3,0,c_n_reg1*p_postreg/12*IF(G$3>=c_reg_m,1,0)+c_n_reg2*p_postreg/12*IF(G$3>=c_m2+c_rt,1,0)) | H29: =IF(H$3>ROUND(p_stop_det,0)+3,0,c_n_reg1*p_postreg/12*IF(H$3>=c_reg_m,1,0)+c_n_reg2*p_postreg/12*IF(H$3>=c_m2+c_rt,1,0)) | I29: =IF(I$3>ROUND(p_stop_det,0)+3,0,c_n_reg1*p_postreg/12*IF(I$3>=c_reg_m,1,0)+c_n_reg2*p_postreg/12*IF(I$3>=c_m2+c_rt,1,0)) | J29: =IF(J$3>ROUND(p_stop_det,0)+3,0,c_n_reg1*p_postreg/12*IF(J$3>=c_reg_m,1,0)+c_n_reg2*p_postreg/12*IF(J$3>=c_m2+c_rt,1,0)) | K29: =IF(K$3>ROUND(p_stop_det,0)+3,0,c_n_reg1*p_postreg/12*IF(K$3>=c_reg_m,1,0)+c_n_reg2*p_postreg/12*IF(K$3>=c_m2+c_rt,1,0)) | ... BK29: =IF(BK$3>ROUND(p_stop_det,0)+3,0,c_n_reg1*p_postreg/12*IF(BK$3>=c_reg_m,1,0)+c_n_reg2*p_postreg/12*IF(BK$3>=c_m2+c_rt,1,0))
A30: Gastos de arranque | D30: =SUMIF(u_month,D$3,u_used) | E30: =SUMIF(u_month,E$3,u_used) | F30: =SUMIF(u_month,F$3,u_used) | G30: =SUMIF(u_month,G$3,u_used) | H30: =SUMIF(u_month,H$3,u_used) | I30: =SUMIF(u_month,I$3,u_used) | J30: =SUMIF(u_month,J$3,u_used) | K30: =SUMIF(u_month,K$3,u_used) | ... BK30: =SUMIF(u_month,BK$3,u_used)
A31: Registros sanitarios | D31: =IF(D$3=c_rs_pay_m,SUM(SKUs!$D$6:$D$24)*c_rs_unit,0)+IF(D$3=MAX(1,MIN(60,c_m2)),p_n2*c_rs_unit,0) | E31: =IF(E$3=c_rs_pay_m,SUM(SKUs!$D$6:$D$24)*c_rs_unit,0)+IF(E$3=MAX(1,MIN(60,c_m2)),p_n2*c_rs_unit,0) | F31: =IF(F$3=c_rs_pay_m,SUM(SKUs!$D$6:$D$24)*c_rs_unit,0)+IF(F$3=MAX(1,MIN(60,c_m2)),p_n2*c_rs_unit,0) | G31: =IF(G$3=c_rs_pay_m,SUM(SKUs!$D$6:$D$24)*c_rs_unit,0)+IF(G$3=MAX(1,MIN(60,c_m2)),p_n2*c_rs_unit,0) | H31: =IF(H$3=c_rs_pay_m,SUM(SKUs!$D$6:$D$24)*c_rs_unit,0)+IF(H$3=MAX(1,MIN(60,c_m2)),p_n2*c_rs_unit,0) | I31: =IF(I$3=c_rs_pay_m,SUM(SKUs!$D$6:$D$24)*c_rs_unit,0)+IF(I$3=MAX(1,MIN(60,c_m2)),p_n2*c_rs_unit,0) | J31: =IF(J$3=c_rs_pay_m,SUM(SKUs!$D$6:$D$24)*c_rs_unit,0)+IF(J$3=MAX(1,MIN(60,c_m2)),p_n2*c_rs_unit,0) | K31: =IF(K$3=c_rs_pay_m,SUM(SKUs!$D$6:$D$24)*c_rs_unit,0)+IF(K$3=MAX(1,MIN(60,c_m2)),p_n2*c_rs_unit,0) | ... BK31: =IF(BK$3=c_rs_pay_m,SUM(SKUs!$D$6:$D$24)*c_rs_unit,0)+IF(BK$3=MAX(1,MIN(60,c_m2)),p_n2*c_rs_unit,0)
A32: Cargos anuales | D32: =IF(D$3>ROUND(p_stop_det,0)+3,0,IF(OR(D$3=1,D$3=13,D$3=25,D$3=37,D$3=49),c_annual,0)) | E32: =IF(E$3>ROUND(p_stop_det,0)+3,0,IF(OR(E$3=1,E$3=13,E$3=25,E$3=37,E$3=49),c_annual,0)) | F32: =IF(F$3>ROUND(p_stop_det,0)+3,0,IF(OR(F$3=1,F$3=13,F$3=25,F$3=37,F$3=49),c_annual,0)) | G32: =IF(G$3>ROUND(p_stop_det,0)+3,0,IF(OR(G$3=1,G$3=13,G$3=25,G$3=37,G$3=49),c_annual,0)) | H32: =IF(H$3>ROUND(p_stop_det,0)+3,0,IF(OR(H$3=1,H$3=13,H$3=25,H$3=37,H$3=49),c_annual,0)) | I32: =IF(I$3>ROUND(p_stop_det,0)+3,0,IF(OR(I$3=1,I$3=13,I$3=25,I$3=37,I$3=49),c_annual,0)) | J32: =IF(J$3>ROUND(p_stop_det,0)+3,0,IF(OR(J$3=1,J$3=13,J$3=25,J$3=37,J$3=49),c_annual,0)) | K32: =IF(K$3>ROUND(p_stop_det,0)+3,0,IF(OR(K$3=1,K$3=13,K$3=25,K$3=37,K$3=49),c_annual,0)) | ... BK32: =IF(BK$3>ROUND(p_stop_det,0)+3,0,IF(OR(BK$3=1,BK$3=13,BK$3=25,BK$3=37,BK$3=49),c_annual,0))
A33: Monto afianzado (cumplimiento, sobre la cantidad máxima) | D33: =(s_Rc1/p_realiz*p_pwin_cen*p_bond_css*15/12*D13*(1+IF(AND(D$3-c_cen_start>=15,MOD(D$3-c_cen_start,15)<ROUND(p_bond_tail_css,0)),1,0))+s_Rc2/p_realiz_minsa*p_pwin_cen*p_minsa_occ*p_bond_minsa*D14*(1+IF(AND(D$3-c_cen_start>=12,MOD(D$3-c_cen_start,12)<ROUND(p_bond_tail_minsa,0)),1,0)))*D9*D6 | E33: =(s_Rc1/p_realiz*p_pwin_cen*p_bond_css*15/12*E13*(1+IF(AND(E$3-c_cen_start>=15,MOD(E$3-c_cen_start,15)<ROUND(p_bond_tail_css,0)),1,0))+s_Rc2/p_realiz_minsa*p_pwin_cen*p_minsa_occ*p_bond_minsa*E14*(1+IF(AND(E$3-c_cen_start>=12,MOD(E$3-c_cen_start,12)<ROUND(p_bond_tail_minsa,0)),1,0)))*E9*E6 | F33: =(s_Rc1/p_realiz*p_pwin_cen*p_bond_css*15/12*F13*(1+IF(AND(F$3-c_cen_start>=15,MOD(F$3-c_cen_start,15)<ROUND(p_bond_tail_css,0)),1,0))+s_Rc2/p_realiz_minsa*p_pwin_cen*p_minsa_occ*p_bond_minsa*F14*(1+IF(AND(F$3-c_cen_start>=12,MOD(F$3-c_cen_start,12)<ROUND(p_bond_tail_minsa,0)),1,0)))*F9*F6 | G33: =(s_Rc1/p_realiz*p_pwin_cen*p_bond_css*15/12*G13*(1+IF(AND(G$3-c_cen_start>=15,MOD(G$3-c_cen_start,15)<ROUND(p_bond_tail_css,0)),1,0))+s_Rc2/p_realiz_minsa*p_pwin_cen*p_minsa_occ*p_bond_minsa*G14*(1+IF(AND(G$3-c_cen_start>=12,MOD(G$3-c_cen_start,12)<ROUND(p_bond_tail_minsa,0)),1,0)))*G9*G6 | H33: =(s_Rc1/p_realiz*p_pwin_cen*p_bond_css*15/12*H13*(1+IF(AND(H$3-c_cen_start>=15,MOD(H$3-c_cen_start,15)<ROUND(p_bond_tail_css,0)),1,0))+s_Rc2/p_realiz_minsa*p_pwin_cen*p_minsa_occ*p_bond_minsa*H14*(1+IF(AND(H$3-c_cen_start>=12,MOD(H$3-c_cen_start,12)<ROUND(p_bond_tail_minsa,0)),1,0)))*H9*H6 | I33: =(s_Rc1/p_realiz*p_pwin_cen*p_bond_css*15/12*I13*(1+IF(AND(I$3-c_cen_start>=15,MOD(I$3-c_cen_start,15)<ROUND(p_bond_tail_css,0)),1,0))+s_Rc2/p_realiz_minsa*p_pwin_cen*p_minsa_occ*p_bond_minsa*I14*(1+IF(AND(I$3-c_cen_start>=12,MOD(I$3-c_cen_start,12)<ROUND(p_bond_tail_minsa,0)),1,0)))*I9*I6 | J33: =(s_Rc1/p_realiz*p_pwin_cen*p_bond_css*15/12*J13*(1+IF(AND(J$3-c_cen_start>=15,MOD(J$3-c_cen_start,15)<ROUND(p_bond_tail_css,0)),1,0))+s_Rc2/p_realiz_minsa*p_pwin_cen*p_minsa_occ*p_bond_minsa*J14*(1+IF(AND(J$3-c_cen_start>=12,MOD(J$3-c_cen_start,12)<ROUND(p_bond_tail_minsa,0)),1,0)))*J9*J6 | K33: =(s_Rc1/p_realiz*p_pwin_cen*p_bond_css*15/12*K13*(1+IF(AND(K$3-c_cen_start>=15,MOD(K$3-c_cen_start,15)<ROUND(p_bond_tail_css,0)),1,0))+s_Rc2/p_realiz_minsa*p_pwin_cen*p_minsa_occ*p_bond_minsa*K14*(1+IF(AND(K$3-c_cen_start>=12,MOD(K$3-c_cen_start,12)<ROUND(p_bond_tail_minsa,0)),1,0)))*K9*K6 | ... BK33: =(s_Rc1/p_realiz*p_pwin_cen*p_bond_css*15/12*BK13*(1+IF(AND(BK$3-c_cen_start>=15,MOD(BK$3-c_cen_start,15)<ROUND(p_bond_tail_css,0)),1,0))+s_Rc2/p_realiz_minsa*p_pwin_cen*p_minsa_occ*p_bond_minsa*BK14*(1+IF(AND(BK$3-c_cen_start>=12,MOD(BK$3-c_cen_start,12)<ROUND(p_bond_tail_minsa,0)),1,0)))*BK9*BK6
A34: Fianza de propuesta vigente (LPU) | D34: =p_bid_bond*s_bid*15/12*D13*IF(AND(D$3>=c_cen_start-c_bid_m,MOD(D$3-(c_cen_start-c_bid_m),15)<c_bid_m),1,0)*D6 | E34: =p_bid_bond*s_bid*15/12*E13*IF(AND(E$3>=c_cen_start-c_bid_m,MOD(E$3-(c_cen_start-c_bid_m),15)<c_bid_m),1,0)*E6 | F34: =p_bid_bond*s_bid*15/12*F13*IF(AND(F$3>=c_cen_start-c_bid_m,MOD(F$3-(c_cen_start-c_bid_m),15)<c_bid_m),1,0)*F6 | G34: =p_bid_bond*s_bid*15/12*G13*IF(AND(G$3>=c_cen_start-c_bid_m,MOD(G$3-(c_cen_start-c_bid_m),15)<c_bid_m),1,0)*G6 | H34: =p_bid_bond*s_bid*15/12*H13*IF(AND(H$3>=c_cen_start-c_bid_m,MOD(H$3-(c_cen_start-c_bid_m),15)<c_bid_m),1,0)*H6 | I34: =p_bid_bond*s_bid*15/12*I13*IF(AND(I$3>=c_cen_start-c_bid_m,MOD(I$3-(c_cen_start-c_bid_m),15)<c_bid_m),1,0)*I6 | J34: =p_bid_bond*s_bid*15/12*J13*IF(AND(J$3>=c_cen_start-c_bid_m,MOD(J$3-(c_cen_start-c_bid_m),15)<c_bid_m),1,0)*J6 | K34: =p_bid_bond*s_bid*15/12*K13*IF(AND(K$3>=c_cen_start-c_bid_m,MOD(K$3-(c_cen_start-c_bid_m),15)<c_bid_m),1,0)*K6 | ... BK34: =p_bid_bond*s_bid*15/12*BK13*IF(AND(BK$3>=c_cen_start-c_bid_m,MOD(BK$3-(c_cen_start-c_bid_m),15)<c_bid_m),1,0)*BK6
A35: Colateral inmovilizado | C35: 0 | D35: =(D33+D34)*p_collat | E35: =(E33+E34)*p_collat | F35: =(F33+F34)*p_collat | G35: =(G33+G34)*p_collat | H35: =(H33+H34)*p_collat | I35: =(I33+I34)*p_collat | J35: =(J33+J34)*p_collat | K35: =(K33+K34)*p_collat | ... BK35: =(BK33+BK34)*p_collat
A36: Cambio en colateral | D36: =D35-C35 | E36: =E35-D35 | F36: =F35-E35 | G36: =G35-F35 | H36: =H35-G35 | I36: =I35-H35 | J36: =J35-I35 | K36: =K35-J35 | ... BK36: =BK35-BJ35
A37: Prima de fianzas | D37: =(D33+D34)*p_bond_prem/12 | E37: =(E33+E34)*p_bond_prem/12 | F37: =(F33+F34)*p_bond_prem/12 | G37: =(G33+G34)*p_bond_prem/12 | H37: =(H33+H34)*p_bond_prem/12 | I37: =(I33+I34)*p_bond_prem/12 | J37: =(J33+J34)*p_bond_prem/12 | K37: =(K33+K34)*p_bond_prem/12 | ... BK37: =(BK33+BK34)*p_bond_prem/12
A38: Costo de factoring | D38: =p_fact_share*D17*(1-p_baddebt)*p_fact_cost*c_dso_m | E38: =p_fact_share*E17*(1-p_baddebt)*p_fact_cost*c_dso_m | F38: =p_fact_share*F17*(1-p_baddebt)*p_fact_cost*c_dso_m | G38: =p_fact_share*G17*(1-p_baddebt)*p_fact_cost*c_dso_m | H38: =p_fact_share*H17*(1-p_baddebt)*p_fact_cost*c_dso_m | I38: =p_fact_share*I17*(1-p_baddebt)*p_fact_cost*c_dso_m | J38: =p_fact_share*J17*(1-p_baddebt)*p_fact_cost*c_dso_m | K38: =p_fact_share*K17*(1-p_baddebt)*p_fact_cost*c_dso_m | ... BK38: =p_fact_share*BK17*(1-p_baddebt)*p_fact_cost*c_dso_m
